Workbook
Name FamilyWeightMatrix: 'Arsenal Profile'!$E$4:$U$20
Name PitchClass: 'Arsenal Profile'!$A$3:$C$19
Name PlayerArsenalVectors: 'Arsenal Profile'!$W$5:$AM$77

Sheet braves_19_25
A1: player_id | B1: player_name | C1: pitch_type | D1: usage | E1: xwoba | F1: spin_rate | G1: effective_speed | H1: release_extension | I1: api_break_z_with_gravity | J1: api_break_x_arm | K1: api_break_x_batter_in | L1: release_pos_z | M1: release_pos_x | N1: xslg | O1: arm_angle | P1: pitches | Q1: total_pitches | R1: pitch_percent
A2: 608331 | B2: Fried, Max | C2: FF | D2: 30.8 | E2: 0.327 | F2: 2138 | G2: 94.37 | H2: 6.37 | I2: 1.56732 | J2: 0.13521 | K2: -0.08096 | L2: 6.06 | M2: 1.24 | N2: 0.397 | O2: 52.8 | P2: 4947 | Q2: 12948 | R2: 0.38206673
A3: 608331 | B3: Fried, Max | C3: FC | D3: 1.3 | E3: 0.332 | F3: 2361 | G3: 88.85 | H3: 6.4 | I3: 2.6551 | J3: -0.2854 | K3: 0.11104 | L3: 5.86 | M3: 1.5 | N3: 0.467 | O3: 44.7 | P3: 202 | Q3: 12948 | R3: 0.015600865
A4: 608331 | B4: Fried, Max | C4: CU | D4: 18.6 | E4: 0.204 | F4: 2770 | G4: 73.83 | H4: 6.15 | I4: 5.59075 | J4: -0.78738 | K4: 0.52068 | L4: 6.08 | M4: 1.36 | N4: 0.255 | O4: 53.7 | P4: 2989 | Q4: 12948 | R4: 0.23084646
A5: 608331 | B5: Fried, Max | C5: SL | D5: 12 | E5: 0.281 | F5: 2480 | G5: 84.99 | H5: 6.1 | I5: 3.20238 | J5: -0.67054 | K5: 0.27798 | L5: 5.93 | M5: 1.54 | N5: 0.372 | O5: 48.2 | P5: 1921 | Q5: 12948 | R5: 0.14836268
A6: 608331 | B6: Fried, Max | C6: SI | D6: 9.3 | E6: 0.307 | F6: 2030 | G6: 93.79 | H6: 6.45 | I6: 1.81553 | J6: 0.87371 | K6: -0.17539 | L6: 6.02 | M6: 1.2 | N6: 0.384 | O6: 51.3 | P6: 1500 | Q6: 12948 | R6: 0.11584801
A7: 608331 | B7: Fried, Max | C7: CH | D7: 7.1 | E7: 0.245 | F7: 1433 | G7: 86.44 | H7: 6.53 | I7: 2.70483 | J7: 1.02873 | K7: -0.83829 | L7: 5.75 | M7: 1.62 | N7: 0.319 | O7: 43.4 | P7: 1142 | Q7: 12948 | R7: 0.08819895
A8: 608331 | B8: Fried, Max | C8: ST | D8: 1.5 | E8: 0.17 | F8: 2737 | G8: 80.95 | H8: 6.37 | I8: 3.96814 | J8: -1.25073 | K8: 0.37794 | L8: 5.89 | M8: 1.48 | N8: 0.159 | O8: 46.1 | P8: 247 | Q8: 12948 | R8: 0.019076305
A9: 450203 | B9: Morton, Charlie | C9: SI | D9: 6.5 | E9: 0.395 | F9: 2142 | G9: 94.18 | H9: 6.24 | I9: 2.15906 | J9: 1.44213 | K9: 1.09535 | L9: 5.45 | M9: -2.26 | N9: 0.48 | O9: 21.7 | P9: 1158 | Q9: 11546 | R9: 0.10029447
A10: 450203 | B10: Morton, Charlie | C10: FF | D10: 21.2 | E10: 0.356 | F10: 2320 | G10: 94.76 | H10: 6.21 | I10: 1.55983 | J10: 1.05091 | K10: -0.16746 | L10: 5.5 | M10: -2.27 | N10: 0.469 | O10: 22.9 | P10: 3790 | Q10: 11546 | R10: 0.32825221
A11: 450203 | B11: Morton, Charlie | C11: CH | D11: 5.6 | E11: 0.346 | F11: 2144 | G11: 85.9 | H11: 6.27 | I11: 3.00529 | J11: 1.45204 | K11: -0.38361 | L11: 5.37 | M11: -2.4 | N11: 0.434 | O11: 20 | P11: 1006 | Q11: 11546 | R11: 0.087129742
A12: 450203 | B12: Morton, Charlie | C12: FC | D12: 5.4 | E12: 0.415 | F12: 2478 | G12: 88.55 | H12: 6.21 | I12: 2.45421 | J12: -0.08624 | K12: -0.0411 | L12: 5.41 | M12: -2.37 | N12: 0.597 | O12: 20.8 | P12: 969 | Q12: 11546 | R12: 0.083925169
A13: 450203 | B13: Morton, Charlie | C13: CU | D13: 25.9 | E13: 0.247 | F13: 3074 | G13: 81.06 | H13: 6.15 | I13: 4.20357 | J13: -1.23047 | K13: 0.16382 | L13: 5.4 | M13: -2.42 | N13: 0.274 | O13: 21.1 | P13: 4623 | Q13: 11546 | R13: 0.40039841
A14: 675911 | B14: Strider, Spencer | C14: PO | D14: 0 | F14: 2209 | G14: 90.7 | H14: 6.3 | I14: 1.28 | J14: 0.7 | K14: -0.7 | L14: 6.09 | M14: -2.19 | O14: 38.7 | P14: 1 | Q14: 7703 | R14: 0.00012981955
A15: 675911 | B15: Strider, Spencer | C15: FF | D15: 59.1 | E15: 0.329 | F15: 2339 | G15: 98.26 | H15: 6.98 | I15: 0.95031 | J15: 0.54209 | K15: -0.07393 | L15: 5.81 | M15: -1.93 | N15: 0.43 | O15: 46.3 | P15: 4553 | Q15: 7703 | R15: 0.59106841
A16: 675911 | B16: Strider, Spencer | C16: CH | D16: 5.7 | E16: 0.206 | F16: 2157 | G16: 88.37 | H16: 7.02 | I16: 2.13105 | J16: 1.21194 | K16: -1.09303 | L16: 5.72 | M16: -2.14 | N16: 0.249 | O16: 42.8 | P16: 439 | Q16: 7703 | R16: 0.056990783
A17: 675911 | B17: Strider, Spencer | C17: SL | D17: 32.5 | E17: 0.224 | F17: 2335 | G17: 86.6 | H17: 6.96 | I17: 2.97651 | J17: -0.44432 | K17: -0.06346 | L17: 5.74 | M17: -1.99 | N17: 0.268 | O17: 44.8 | P17: 2501 | Q17: 7703 | R17: 0.3246787
A18: 675911 | B18: Strider, Spencer | C18: CU | D18: 2.7 | E18: 0.256 | F18: 2655 | G18: 79.43 | H18: 6.87 | I18: 4.24249 | J18: -0.82861 | K18: 0.35139 | L18: 5.84 | M18: -1.76 | N18: 0.292 | O18: 43.9 | P18: 209 | Q18: 7703 | R18: 0.027132286
A19: 693821 | B19: Elder, Bryce | C19: SI | D19: 40.6 | E19: 0.357 | F19: 2019 | G19: 89.97 | H19: 6.03 | I19: 2.07363 | J19: 1.14847 | K19: 0.31426 | L19: 6.48 | M19: -1.16 | N19: 0.447 | O19: 51.4 | P19: 2884 | Q19: 7100 | R19: 0.40619718
A20: 693821 | B20: Elder, Bryce | C20: SL | D20: 33.8 | E20: 0.302 | F20: 2445 | G20: 83.04 | H20: 6.03 | I20: 3.37537 | J20: -0.06556 | K20: -0.00658 | L20: 6.52 | M20: -1.03 | N20: 0.408 | O20: 53.9 | P20: 2397 | Q20: 7100 | R20: 0.33760563
A21: 693821 | B21: Elder, Bryce | C21: FC | D21: 0 | E21: 0.079 | F21: 2512 | G21: 86.6 | H21: 6 | I21: 2.68 | J21: -0.32 | K21: -0.32 | L21: 6.46 | M21: -1.45 | N21: 0.088 | O21: 56.7 | P21: 1 | Q21: 7100 | R21: 0.00014084507
A22: 693821 | B22: Elder, Bryce | C22: FF | D22: 13.2 | E22: 0.342 | F22: 2170 | G22: 91.26 | H22: 6.03 | I22: 1.45462 | J22: 0.28115 | K22: -0.22524 | L22: 6.49 | M22: -1.1 | N22: 0.451 | O22: 52 | P22: 936 | Q22: 7100 | R22: 0.13183099
A23: 693821 | B23: Elder, Bryce | C23: CH | D23: 12.4 | E23: 0.309 | F23: 2125 | G23: 85.42 | H23: 5.97 | I23: 2.7383 | J23: 0.96039 | K23: -0.45367 | L23: 6.5 | M23: -1.15 | N23: 0.405 | O23: 52.1 | P23: 882 | Q23: 7100 | R23: 0.12422535
A24: 519242 | B24: Sale, Chris | C24: SI | D24: 2.8 | E24: 0.377 | F24: 2094 | G24: 94.25 | H24: 6.59 | I24: 2.3904 | J24: 1.49244 | K24: -0.18676 | L24: 4.96 | M24: 3.13 | N24: 0.445 | O24: 8.8 | P24: 275 | Q24: 4846 | R24: 0.056747833
A25: 519242 | B25: Sale, Chris | C25: FF | D25: 19.6 | E25: 0.322 | F25: 2251 | G25: 95.15 | H25: 6.62 | I25: 1.73782 | J25: 1.24409 | K25: -0.88604 | L25: 5.1 | M25: 3.07 | N25: 0.405 | O25: 11 | P25: 1922 | Q25: 4846 | R25: 0.39661577
A26: 519242 | B26: Sale, Chris | C26: CH | D26: 5.6 | E26: 0.255 | F26: 1868 | G26: 87.09 | H26: 6.51 | I26: 3.0294 | J26: 1.3563 | K26: -1.27287 | L26: 4.77 | M26: 3.16 | N26: 0.338 | O26: 5.9 | P26: 554 | Q26: 4846 | R26: 0.11432109
... A55: 445926 | B55: Chavez, Jesse | C55: CH | D55: 8.3 | E55: 0.31 | F55: 1833 | G55: 85.15 | H55: 6.33 | I55: 2.98276 | J55: 1.32603 | K55: -0.75491 | L55: 5.11 | M55: -1.61 | N55: 0.385 | O55: 22.3 | P55: 428 | Q55: 3213 | R55: 0.13320884
A56: 445926 | B56: Chavez, Jesse | C56: PO | D56: 0 | F56: 2157 | G56: 88.7 | H56: 6.2 | I56: 1.77 | J56: 0.87 | K56: 0.87 | L56: 5.15 | M56: -1.75 | O56: 18.5 | P56: 1 | Q56: 3213 | R56: 0.00031123561
A57: 445926 | B57: Chavez, Jesse | C57: CU | D57: 2.5 | E57: 0.184 | F57: 2562 | G57: 75.61 | H57: 6.32 | I57: 4.63116 | J57: -1.31713 | K57: -0.73791 | L57: 5.26 | M57: -1.55 | N57: 0.241 | O57: 26.7 | P57: 129 | Q57: 3213 | R57: 0.040149393
A58: 445926 | B58: Chavez, Jesse | C58: SI | D58: 17.9 | E58: 0.326 | F58: 1995 | G58: 90.89 | H58: 6.23 | I58: 2.12298 | J58: 1.35245 | K58: 0.58831 | L58: 5.11 | M58: -1.51 | N58: 0.435 | O58: 21 | P58: 922 | Q58: 3213 | R58: 0.28695923
A59: 628452 | B59: Iglesias, Raisel | C59: SL | D59: 7.9 | E59: 0.253 | F59: 2645 | G59: 83.99 | H59: 6.06 | I59: 2.82986 | J59: -0.80553 | K59: -0.44618 | L59: 5.49 | M59: -1.79 | N59: 0.373 | O59: 32.9 | P59: 493 | Q59: 3173 | R59: 0.15537346
A60: 628452 | B60: Iglesias, Raisel | C60: SI | D60: 9.3 | E60: 0.337 | F60: 2328 | G60: 94.65 | H60: 6.2 | I60: 1.77276 | J60: 1.39465 | K60: 0.50467 | L60: 5.48 | M60: -1.83 | N60: 0.397 | O60: 31.6 | P60: 583 | Q60: 3173 | R60: 0.18373779
A61: 628452 | B61: Iglesias, Raisel | C61: CH | D61: 15.7 | E61: 0.222 | F61: 1974 | G61: 89 | H61: 6.19 | I61: 2.5007 | J61: 1.33153 | K61: -0.48331 | L61: 5.41 | M61: -1.87 | N61: 0.279 | O61: 30.3 | P61: 983 | Q61: 3173 | R61: 0.30980145
A62: 628452 | B62: Iglesias, Raisel | C62: FF | D62: 17.8 | E62: 0.279 | F62: 2321 | G62: 94.91 | H62: 6.17 | I62: 1.26637 | J62: 0.73525 | K62: -0.15058 | L62: 5.48 | M62: -1.84 | N62: 0.394 | O62: 31.8 | P62: 1114 | Q62: 3173 | R62: 0.3510873
A63: 592426 | B63: Jackson, Luke | C63: SL | D63: 31.7 | E63: 0.232 | F63: 2446 | G63: 87.94 | H63: 6.47 | I63: 3.49258 | J63: -0.14026 | K63: -0.03076 | L63: 6.33 | M63: -2.54 | N63: 0.271 | O63: 49.2 | P63: 1589 | Q63: 3136 | R63: 0.50669643
A64: 592426 | B64: Jackson, Luke | C64: FC | D64: 0.2 | E64: 0.549 | F64: 2393 | G64: 90.9 | H64: 6.68 | I64: 2.139 | J64: -0.153 | K64: -0.173 | L64: 6.39 | M64: -2.64 | N64: 0.469 | O64: 42.7 | P64: 10 | Q64: 3136 | R64: 0.0031887755
A65: 592426 | B65: Jackson, Luke | C65: FF | D65: 22.6 | E65: 0.387 | F65: 2265 | G65: 96.3 | H65: 6.7 | I65: 1.02605 | J65: 0.59161 | K65: 0.06991 | L65: 6.46 | M65: -2.18 | N65: 0.502 | O65: 53 | P65: 1133 | Q65: 3136 | R65: 0.36128827
A66: 592426 | B66: Jackson, Luke | C66: CU | D66: 8 | E66: 0.299 | F66: 2498 | G66: 84.04 | H66: 6.4 | I66: 4.30483 | J66: -0.48948 | K66: 0.15275 | L66: 6.41 | M66: -2.61 | N66: 0.403 | O66: 51.2 | P66: 404 | Q66: 3136 | R66: 0.12882653
A67: 669276 | B67: Lee, Dylan | C67: FF | D67: 36.3 | E67: 0.326 | F67: 2285 | G67: 92.72 | H67: 6.34 | I67: 1.0454 | J67: 0.63493 | K67: -0.16514 | L67: 6.51 | M67: 1.67 | N67: 0.468 | O67: 47.5 | P67: 1139 | Q67: 3134 | R67: 0.36343331
A68: 669276 | B68: Lee, Dylan | C68: SI | D68: 0 | E68: 0.164 | F68: 2060 | G68: 92.1 | H68: 6.7 | I68: 1.32 | J68: 0.42 | K68: -0.42 | L68: 6.17 | M68: 1.66 | N68: 0.229 | O68: 47.2 | P68: 1 | Q68: 3134 | R68: 0.00031908105
...

Sheet Arsenal Profile
A1: Arsenal Similarity
A3: Classification | E3: Family Weight Matrix | W3: Player Arsenal Vectors
A4: FF | B4: Four Seam | C4: Fastball | F4: FF | G4: SI | H4: SL | I4: CU | J4: FS | K4: FC | L4: CH | M4: ST | N4: EP | O4: FA | P4: CS | Q4: SV | R4: KC | S4: FO | T4: SC | U4: KN | X4: FF | Y4: SI | Z4: SL | AA4: CU | AB4: FS | AC4: FC | AD4: CH | AE4: ST | AF4: EP | AG4: FA | AH4: CS | AI4: SV | AJ4: KC | AK4: FO | AL4: SC | AM4: KN | AN4: Norm
A5: SI | B5: Sinker/Two Seam | C5: Fastball | E5: FF | F5: =IF(F$4=$E5,1,IF(_xlfn.XLOOKUP(F$4,$A$4:$A$19,$C$4:$C$19)=_xlfn.XLOOKUP($E5,$A$4:$A$19,$C$4:$C$19),0.7,0)) -> 1 | G5: =IF(G$4=$E5,1,IF(_xlfn.XLOOKUP(G$4,$A$4:$A$19,$C$4:$C$19)=_xlfn.XLOOKUP($E5,$A$4:$A$19,$C$4:$C$19),0.7,0)) -> 0.7 | H5: =IF(H$4=$E5,1,IF(_xlfn.XLOOKUP(H$4,$A$4:$A$19,$C$4:$C$19)=_xlfn.XLOOKUP($E5,$A$4:$A$19,$C$4:$C$19),0.7,0)) -> 0 | I5: =IF(I$4=$E5,1,IF(_xlfn.XLOOKUP(I$4,$A$4:$A$19,$C$4:$C$19)=_xlfn.XLOOKUP($E5,$A$4:$A$19,$C$4:$C$19),0.7,0)) -> 0 | J5: =IF(J$4=$E5,1,IF(_xlfn.XLOOKUP(J$4,$A$4:$A$19,$C$4:$C$19)=_xlfn.XLOOKUP($E5,$A$4:$A$19,$C$4:$C$19),0.7,0)) -> 0 | K5: =IF(K$4=$E5,1,IF(_xlfn.XLOOKUP(K$4,$A$4:$A$19,$C$4:$C$19)=_xlfn.XLOOKUP($E5,$A$4:$A$19,$C$4:$C$19),0.7,0)) -> 0.7 | L5: =IF(L$4=$E5,1,IF(_xlfn.XLOOKUP(L$4,$A$4:$A$19,$C$4:$C$19)=_xlfn.XLOOKUP($E5,$A$4:$A$19,$C$4:$C$19),0.7,0)) -> 0 | M5: =IF(M$4=$E5,1,IF(_xlfn.XLOOKUP(M$4,$A$4:$A$19,$C$4:$C$19)=_xlfn.XLOOKUP($E5,$A$4:$A$19,$C$4:$C$19),0.7,0)) -> 0 | ... U5: =IF(U$4=$E5,1,IF(_xlfn.XLOOKUP(U$4,$A$4:$A$19,$C$4:$C$19)=_xlfn.XLOOKUP($E5,$A$4:$A$19,$C$4:$C$19),0.7,0)) -> 0 | W5: {=_xlfn.UNIQUE(braves_19_25__2[player_name])} -> Fried, Max | X5: {=IFERROR(_xlfn.XLOOKUP($W5&X$4,braves_19_25!$B:$B&braves_19_25!$C:$C,braves_19_25!$R:$R),0)} -> 0.38206673 | Y5: {=IFERROR(_xlfn.XLOOKUP($W5&Y$4,braves_19_25!$B:$B&braves_19_25!$C:$C,braves_19_25!$R:$R),0)} -> 0.11584801 | Z5: {=IFERROR(_xlfn.XLOOKUP($W5&Z$4,braves_19_25!$B:$B&braves_19_25!$C:$C,braves_19_25!$R:$R),0)} -> 0.14836268 | AA5: {=IFERROR(_xlfn.XLOOKUP($W5&AA$4,braves_19_25!$B:$B&braves_19_25!$C:$C,braves_19_25!$R:$R),0)} -> 0.23084646 | AB5: {=IFERROR(_xlfn.XLOOKUP($W5&AB$4,braves_19_25!$B:$B&braves_19_25!$C:$C,braves_19_25!$R:$R),0)} -> 0 | AC5: {=IFERROR(_xlfn.XLOOKUP($W5&AC$4,braves_19_25!$B:$B&braves_19_25!$C:$C,braves_19_25!$R:$R),0)} -> 0.015600865 | AD5: {=IFERROR(_xlfn.XLOOKUP($W5&AD$4,braves_19_25!$B:$B&braves_19_25!$C:$C,braves_19_25!$R:$R),0)} -> 0.08819895 | AE5: {=IFERROR(_xlfn.XLOOKUP($W5&AE$4,braves_19_25!$B:$B&braves_19_25!$C:$C,braves_19_25!$R:$R),0)} -> 0.019076305 | ... AM5: {=IFERROR(_xlfn.XLOOKUP($W5&AM$4,braves_19_25!$B:$B&braves_19_25!$C:$C,braves_19_25!$R:$R),0)} -> 0 | AN5: {=SQRT( MMULT( MMULT( $X5:$AM5, $F$5:$U$20 ), TRANSPOSE($X5:$AM5) ) )} -> 0.56558586
A6: SL | B6: Slider | C6: Hbreak | E6: SI | F6: =IF(F$4=$E6,1,IF(_xlfn.XLOOKUP(F$4,$A$4:$A$19,$C$4:$C$19)=_xlfn.XLOOKUP($E6,$A$4:$A$19,$C$4:$C$19),0.7,0)) -> 0.7 | G6: =IF(G$4=$E6,1,IF(_xlfn.XLOOKUP(G$4,$A$4:$A$19,$C$4:$C$19)=_xlfn.XLOOKUP($E6,$A$4:$A$19,$C$4:$C$19),0.7,0)) -> 1 | H6: =IF(H$4=$E6,1,IF(_xlfn.XLOOKUP(H$4,$A$4:$A$19,$C$4:$C$19)=_xlfn.XLOOKUP($E6,$A$4:$A$19,$C$4:$C$19),0.7,0)) -> 0 | I6: =IF(I$4=$E6,1,IF(_xlfn.XLOOKUP(I$4,$A$4:$A$19,$C$4:$C$19)=_xlfn.XLOOKUP($E6,$A$4:$A$19,$C$4:$C$19),0.7,0)) -> 0 | J6: =IF(J$4=$E6,1,IF(_xlfn.XLOOKUP(J$4,$A$4:$A$19,$C$4:$C$19)=_xlfn.XLOOKUP($E6,$A$4:$A$19,$C$4:$C$19),0.7,0)) -> 0 | K6: =IF(K$4=$E6,1,IF(_xlfn.XLOOKUP(K$4,$A$4:$A$19,$C$4:$C$19)=_xlfn.XLOOKUP($E6,$A$4:$A$19,$C$4:$C$19),0.7,0)) -> 0.7 | L6: =IF(L$4=$E6,1,IF(_xlfn.XLOOKUP(L$4,$A$4:$A$19,$C$4:$C$19)=_xlfn.XLOOKUP($E6,$A$4:$A$19,$C$4:$C$19),0.7,0)) -> 0 | M6: =IF(M$4=$E6,1,IF(_xlfn.XLOOKUP(M$4,$A$4:$A$19,$C$4:$C$19)=_xlfn.XLOOKUP($E6,$A$4:$A$19,$C$4:$C$19),0.7,0)) -> 0 | ... U6: =IF(U$4=$E6,1,IF(_xlfn.XLOOKUP(U$4,$A$4:$A$19,$C$4:$C$19)=_xlfn.XLOOKUP($E6,$A$4:$A$19,$C$4:$C$19),0.7,0)) -> 0 | W6: Morton, Charlie | X6: {=IFERROR(_xlfn.XLOOKUP($W6&X$4,braves_19_25!$B:$B&braves_19_25!$C:$C,braves_19_25!$R:$R),0)} -> 0.32825221 | Y6: {=IFERROR(_xlfn.XLOOKUP($W6&Y$4,braves_19_25!$B:$B&braves_19_25!$C:$C,braves_19_25!$R:$R),0)} -> 0.10029447 | Z6: {=IFERROR(_xlfn.XLOOKUP($W6&Z$4,braves_19_25!$B:$B&braves_19_25!$C:$C,braves_19_25!$R:$R),0)} -> 0 | AA6: {=IFERROR(_xlfn.XLOOKUP($W6&AA$4,braves_19_25!$B:$B&braves_19_25!$C:$C,braves_19_25!$R:$R),0)} -> 0.40039841 | AB6: {=IFERROR(_xlfn.XLOOKUP($W6&AB$4,braves_19_25!$B:$B&braves_19_25!$C:$C,braves_19_25!$R:$R),0)} -> 0 | AC6: {=IFERROR(_xlfn.XLOOKUP($W6&AC$4,braves_19_25!$B:$B&braves_19_25!$C:$C,braves_19_25!$R:$R),0)} -> 0.083925169 | AD6: {=IFERROR(_xlfn.XLOOKUP($W6&AD$4,braves_19_25!$B:$B&braves_19_25!$C:$C,braves_19_25!$R:$R),0)} -> 0.087129742 | AE6: {=IFERROR(_xlfn.XLOOKUP($W6&AE$4,braves_19_25!$B:$B&braves_19_25!$C:$C,braves_19_25!$R:$R),0)} -> 0 | ... AM6: {=IFERROR(_xlfn.XLOOKUP($W6&AM$4,braves_19_25!$B:$B&braves_19_25!$C:$C,braves_19_25!$R:$R),0)} -> 0 | AN6: {=SQRT( MMULT( MMULT( $X6:$AM6, $F$5:$U$20 ), TRANSPOSE($X6:$AM6) ) )} -> 0.62386315
A7: CU | B7: Curveball | C7: Vbreak | E7: SL | F7: =IF(F$4=$E7,1,IF(_xlfn.XLOOKUP(F$4,$A$4:$A$19,$C$4:$C$19)=_xlfn.XLOOKUP($E7,$A$4:$A$19,$C$4:$C$19),0.7,0)) -> 0 | G7: =IF(G$4=$E7,1,IF(_xlfn.XLOOKUP(G$4,$A$4:$A$19,$C$4:$C$19)=_xlfn.XLOOKUP($E7,$A$4:$A$19,$C$4:$C$19),0.7,0)) -> 0 | H7: =IF(H$4=$E7,1,IF(_xlfn.XLOOKUP(H$4,$A$4:$A$19,$C$4:$C$19)=_xlfn.XLOOKUP($E7,$A$4:$A$19,$C$4:$C$19),0.7,0)) -> 1 | I7: =IF(I$4=$E7,1,IF(_xlfn.XLOOKUP(I$4,$A$4:$A$19,$C$4:$C$19)=_xlfn.XLOOKUP($E7,$A$4:$A$19,$C$4:$C$19),0.7,0)) -> 0 | J7: =IF(J$4=$E7,1,IF(_xlfn.XLOOKUP(J$4,$A$4:$A$19,$C$4:$C$19)=_xlfn.XLOOKUP($E7,$A$4:$A$19,$C$4:$C$19),0.7,0)) -> 0 | K7: =IF(K$4=$E7,1,IF(_xlfn.XLOOKUP(K$4,$A$4:$A$19,$C$4:$C$19)=_xlfn.XLOOKUP($E7,$A$4:$A$19,$C$4:$C$19),0.7,0)) -> 0 | L7: =IF(L$4=$E7,1,IF(_xlfn.XLOOKUP(L$4,$A$4:$A$19,$C$4:$C$19)=_xlfn.XLOOKUP($E7,$A$4:$A$19,$C$4:$C$19),0.7,0)) -> 0 | M7: =IF(M$4=$E7,1,IF(_xlfn.XLOOKUP(M$4,$A$4:$A$19,$C$4:$C$19)=_xlfn.XLOOKUP($E7,$A$4:$A$19,$C$4:$C$19),0.7,0)) -> 0.7 | ... U7: =IF(U$4=$E7,1,IF(_xlfn.XLOOKUP(U$4,$A$4:$A$19,$C$4:$C$19)=_xlfn.XLOOKUP($E7,$A$4:$A$19,$C$4:$C$19),0.7,0)) -> 0 | W7: Strider, Spencer | X7: {=IFERROR(_xlfn.XLOOKUP($W7&X$4,braves_19_25!$B:$B&braves_19_25!$C:$C,braves_19_25!$R:$R),0)} -> 0.59106841 | Y7: {=IFERROR(_xlfn.XLOOKUP($W7&Y$4,braves_19_25!$B:$B&braves_19_25!$C:$C,braves_19_25!$R:$R),0)} -> 0 | Z7: {=IFERROR(_xlfn.XLOOKUP($W7&Z$4,braves_19_25!$B:$B&braves_19_25!$C:$C,braves_19_25!$R:$R),0)} -> 0.3246787 | AA7: {=IFERROR(_xlfn.XLOOKUP($W7&AA$4,braves_19_25!$B:$B&braves_19_25!$C:$C,braves_19_25!$R:$R),0)} -> 0.027132286 | AB7: {=IFERROR(_xlfn.XLOOKUP($W7&AB$4,braves_19_25!$B:$B&braves_19_25!$C:$C,braves_19_25!$R:$R),0)} -> 0 | AC7: {=IFERROR(_xlfn.XLOOKUP($W7&AC$4,braves_19_25!$B:$B&braves_19_25!$C:$C,braves_19_25!$R:$R),0)} -> 0 | AD7: {=IFERROR(_xlfn.XLOOKUP($W7&AD$4,braves_19_25!$B:$B&braves_19_25!$C:$C,braves_19_25!$R:$R),0)} -> 0.056990783 | AE7: {=IFERROR(_xlfn.XLOOKUP($W7&AE$4,braves_19_25!$B:$B&braves_19_25!$C:$C,braves_19_25!$R:$R),0)} -> 0 | ... AM7: {=IFERROR(_xlfn.XLOOKUP($W7&AM$4,braves_19_25!$B:$B&braves_19_25!$C:$C,braves_19_25!$R:$R),0)} -> 0 | AN7: {=SQRT( MMULT( MMULT( $X7:$AM7, $F$5:$U$20 ), TRANSPOSE($X7:$AM7) ) )} -> 0.67731989
A8: FS | B8: Split Finger | C8: Offspeed | E8: CU | F8: =IF(F$4=$E8,1,IF(_xlfn.XLOOKUP(F$4,$A$4:$A$19,$C$4:$C$19)=_xlfn.XLOOKUP($E8,$A$4:$A$19,$C$4:$C$19),0.7,0)) -> 0 | G8: =IF(G$4=$E8,1,IF(_xlfn.XLOOKUP(G$4,$A$4:$A$19,$C$4:$C$19)=_xlfn.XLOOKUP($E8,$A$4:$A$19,$C$4:$C$19),0.7,0)) -> 0 | H8: =IF(H$4=$E8,1,IF(_xlfn.XLOOKUP(H$4,$A$4:$A$19,$C$4:$C$19)=_xlfn.XLOOKUP($E8,$A$4:$A$19,$C$4:$C$19),0.7,0)) -> 0 | I8: =IF(I$4=$E8,1,IF(_xlfn.XLOOKUP(I$4,$A$4:$A$19,$C$4:$C$19)=_xlfn.XLOOKUP($E8,$A$4:$A$19,$C$4:$C$19),0.7,0)) -> 1 | J8: =IF(J$4=$E8,1,IF(_xlfn.XLOOKUP(J$4,$A$4:$A$19,$C$4:$C$19)=_xlfn.XLOOKUP($E8,$A$4:$A$19,$C$4:$C$19),0.7,0)) -> 0 | K8: =IF(K$4=$E8,1,IF(_xlfn.XLOOKUP(K$4,$A$4:$A$19,$C$4:$C$19)=_xlfn.XLOOKUP($E8,$A$4:$A$19,$C$4:$C$19),0.7,0)) -> 0 | L8: =IF(L$4=$E8,1,IF(_xlfn.XLOOKUP(L$4,$A$4:$A$19,$C$4:$C$19)=_xlfn.XLOOKUP($E8,$A$4:$A$19,$C$4:$C$19),0.7,0)) -> 0 | M8: =IF(M$4=$E8,1,IF(_xlfn.XLOOKUP(M$4,$A$4:$A$19,$C$4:$C$19)=_xlfn.XLOOKUP($E8,$A$4:$A$19,$C$4:$C$19),0.7,0)) -> 0 | ... U8: =IF(U$4=$E8,1,IF(_xlfn.XLOOKUP(U$4,$A$4:$A$19,$C$4:$C$19)=_xlfn.XLOOKUP($E8,$A$4:$A$19,$C$4:$C$19),0.7,0)) -> 0 | W8: Elder, Bryce | X8: {=IFERROR(_xlfn.XLOOKUP($W8&X$4,braves_19_25!$B:$B&braves_19_25!$C:$C,braves_19_25!$R:$R),0)} -> 0.13183099 | Y8: {=IFERROR(_xlfn.XLOOKUP($W8&Y$4,braves_19_25!$B:$B&braves_19_25!$C:$C,braves_19_25!$R:$R),0)} -> 0.40619718 | Z8: {=IFERROR(_xlfn.XLOOKUP($W8&Z$4,braves_19_25!$B:$B&braves_19_25!$C:$C,braves_19_25!$R:$R),0)} -> 0.33760563 | AA8: {=IFERROR(_xlfn.XLOOKUP($W8&AA$4,braves_19_25!$B:$B&braves_19_25!$C:$C,braves_19_25!$R:$R),0)} -> 0 | AB8: {=IFERROR(_xlfn.XLOOKUP($W8&AB$4,braves_19_25!$B:$B&braves_19_25!$C:$C,braves_19_25!$R:$R),0)} -> 0 | AC8: {=IFERROR(_xlfn.XLOOKUP($W8&AC$4,braves_19_25!$B:$B&braves_19_25!$C:$C,braves_19_25!$R:$R),0)} -> 0.00014084507 | AD8: {=IFERROR(_xlfn.XLOOKUP($W8&AD$4,braves_19_25!$B:$B&braves_19_25!$C:$C,braves_19_25!$R:$R),0)} -> 0.12422535 | AE8: {=IFERROR(_xlfn.XLOOKUP($W8&AE$4,braves_19_25!$B:$B&braves_19_25!$C:$C,braves_19_25!$R:$R),0)} -> 0 | ... AM8: {=IFERROR(_xlfn.XLOOKUP($W8&AM$4,braves_19_25!$B:$B&braves_19_25!$C:$C,braves_19_25!$R:$R),0)} -> 0 | AN8: {=SQRT( MMULT( MMULT( $X8:$AM8, $F$5:$U$20 ), TRANSPOSE($X8:$AM8) ) )} -> 0.62198095
A9: FC | B9: Cutter | C9: Fastball | E9: FS | F9: =IF(F$4=$E9,1,IF(_xlfn.XLOOKUP(F$4,$A$4:$A$19,$C$4:$C$19)=_xlfn.XLOOKUP($E9,$A$4:$A$19,$C$4:$C$19),0.7,0)) -> 0 | G9: =IF(G$4=$E9,1,IF(_xlfn.XLOOKUP(G$4,$A$4:$A$19,$C$4:$C$19)=_xlfn.XLOOKUP($E9,$A$4:$A$19,$C$4:$C$19),0.7,0)) -> 0 | H9: =IF(H$4=$E9,1,IF(_xlfn.XLOOKUP(H$4,$A$4:$A$19,$C$4:$C$19)=_xlfn.XLOOKUP($E9,$A$4:$A$19,$C$4:$C$19),0.7,0)) -> 0 | I9: =IF(I$4=$E9,1,IF(_xlfn.XLOOKUP(I$4,$A$4:$A$19,$C$4:$C$19)=_xlfn.XLOOKUP($E9,$A$4:$A$19,$C$4:$C$19),0.7,0)) -> 0 | J9: =IF(J$4=$E9,1,IF(_xlfn.XLOOKUP(J$4,$A$4:$A$19,$C$4:$C$19)=_xlfn.XLOOKUP($E9,$A$4:$A$19,$C$4:$C$19),0.7,0)) -> 1 | K9: =IF(K$4=$E9,1,IF(_xlfn.XLOOKUP(K$4,$A$4:$A$19,$C$4:$C$19)=_xlfn.XLOOKUP($E9,$A$4:$A$19,$C$4:$C$19),0.7,0)) -> 0 | L9: =IF(L$4=$E9,1,IF(_xlfn.XLOOKUP(L$4,$A$4:$A$19,$C$4:$C$19)=_xlfn.XLOOKUP($E9,$A$4:$A$19,$C$4:$C$19),0.7,0)) -> 0.7 | M9: =IF(M$4=$E9,1,IF(_xlfn.XLOOKUP(M$4,$A$4:$A$19,$C$4:$C$19)=_xlfn.XLOOKUP($E9,$A$4:$A$19,$C$4:$C$19),0.7,0)) -> 0 | ... U9: =IF(U$4=$E9,1,IF(_xlfn.XLOOKUP(U$4,$A$4:$A$19,$C$4:$C$19)=_xlfn.XLOOKUP($E9,$A$4:$A$19,$C$4:$C$19),0.7,0)) -> 0 | W9: Sale, Chris | X9: {=IFERROR(_xlfn.XLOOKUP($W9&X$4,braves_19_25!$B:$B&braves_19_25!$C:$C,braves_19_25!$R:$R),0)} -> 0.39661577 | Y9: {=IFERROR(_xlfn.XLOOKUP($W9&Y$4,braves_19_25!$B:$B&braves_19_25!$C:$C,braves_19_25!$R:$R),0)} -> 0.056747833 | Z9: {=IFERROR(_xlfn.XLOOKUP($W9&Z$4,braves_19_25!$B:$B&braves_19_25!$C:$C,braves_19_25!$R:$R),0)} -> 0.43231531 | AA9: {=IFERROR(_xlfn.XLOOKUP($W9&AA$4,braves_19_25!$B:$B&braves_19_25!$C:$C,braves_19_25!$R:$R),0)} -> 0 | AB9: {=IFERROR(_xlfn.XLOOKUP($W9&AB$4,braves_19_25!$B:$B&braves_19_25!$C:$C,braves_19_25!$R:$R),0)} -> 0 | AC9: {=IFERROR(_xlfn.XLOOKUP($W9&AC$4,braves_19_25!$B:$B&braves_19_25!$C:$C,braves_19_25!$R:$R),0)} -> 0 | AD9: {=IFERROR(_xlfn.XLOOKUP($W9&AD$4,braves_19_25!$B:$B&braves_19_25!$C:$C,braves_19_25!$R:$R),0)} -> 0.11432109 | AE9: {=IFERROR(_xlfn.XLOOKUP($W9&AE$4,braves_19_25!$B:$B&braves_19_25!$C:$C,braves_19_25!$R:$R),0)} -> 0 | ... AM9: {=IFERROR(_xlfn.XLOOKUP($W9&AM$4,braves_19_25!$B:$B&braves_19_25!$C:$C,braves_19_25!$R:$R),0)} -> 0 | AN9: {=SQRT( MMULT( MMULT( $X9:$AM9, $F$5:$U$20 ), TRANSPOSE($X9:$AM9) ) )} -> 0.62609915
A10: CH | B10: Changeup | C10: Offspeed | E10: FC | F10: =IF(F$4=$E10,1,IF(_xlfn.XLOOKUP(F$4,$A$4:$A$19,$C$4:$C$19)=_xlfn.XLOOKUP($E10,$A$4:$A$19,$C$4:$C$19),0.7,0)) -> 0.7 | G10: =IF(G$4=$E10,1,IF(_xlfn.XLOOKUP(G$4,$A$4:$A$19,$C$4:$C$19)=_xlfn.XLOOKUP($E10,$A$4:$A$19,$C$4:$C$19),0.7,0)) -> 0.7 | H10: =IF(H$4=$E10,1,IF(_xlfn.XLOOKUP(H$4,$A$4:$A$19,$C$4:$C$19)=_xlfn.XLOOKUP($E10,$A$4:$A$19,$C$4:$C$19),0.7,0)) -> 0 | I10: =IF(I$4=$E10,1,IF(_xlfn.XLOOKUP(I$4,$A$4:$A$19,$C$4:$C$19)=_xlfn.XLOOKUP($E10,$A$4:$A$19,$C$4:$C$19),0.7,0)) -> 0 | J10: =IF(J$4=$E10,1,IF(_xlfn.XLOOKUP(J$4,$A$4:$A$19,$C$4:$C$19)=_xlfn.XLOOKUP($E10,$A$4:$A$19,$C$4:$C$19),0.7,0)) -> 0 | K10: =IF(K$4=$E10,1,IF(_xlfn.XLOOKUP(K$4,$A$4:$A$19,$C$4:$C$19)=_xlfn.XLOOKUP($E10,$A$4:$A$19,$C$4:$C$19),0.7,0)) -> 1 | L10: =IF(L$4=$E10,1,IF(_xlfn.XLOOKUP(L$4,$A$4:$A$19,$C$4:$C$19)=_xlfn.XLOOKUP($E10,$A$4:$A$19,$C$4:$C$19),0.7,0)) -> 0 | M10: =IF(M$4=$E10,1,IF(_xlfn.XLOOKUP(M$4,$A$4:$A$19,$C$4:$C$19)=_xlfn.XLOOKUP($E10,$A$4:$A$19,$C$4:$C$19),0.7,0)) -> 0 | ... U10: =IF(U$4=$E10,1,IF(_xlfn.XLOOKUP(U$4,$A$4:$A$19,$C$4:$C$19)=_xlfn.XLOOKUP($E10,$A$4:$A$19,$C$4:$C$19),0.7,0)) -> 0 | W10: Anderson, Ian | X10: {=IFERROR(_xlfn.XLOOKUP($W10&X$4,braves_19_25!$B:$B&braves_19_25!$C:$C,braves_19_25!$R:$R),0)} -> 0.4748474 | Y10: {=IFERROR(_xlfn.XLOOKUP($W10&Y$4,braves_19_25!$B:$B&braves_19_25!$C:$C,braves_19_25!$R:$R),0)} -> 0.002736266 | Z10: {=IFERROR(_xlfn.XLOOKUP($W10&Z$4,braves_19_25!$B:$B&braves_19_25!$C:$C,braves_19_25!$R:$R),0)} -> 0 | AA10: {=IFERROR(_xlfn.XLOOKUP($W10&AA$4,braves_19_25!$B:$B&braves_19_25!$C:$C,braves_19_25!$R:$R),0)} -> 0.19364344 | AB10: {=IFERROR(_xlfn.XLOOKUP($W10&AB$4,braves_19_25!$B:$B&braves_19_25!$C:$C,braves_19_25!$R:$R),0)} -> 0 | AC10: {=IFERROR(_xlfn.XLOOKUP($W10&AC$4,braves_19_25!$B:$B&braves_19_25!$C:$C,braves_19_25!$R:$R),0)} -> 0 | AD10: {=IFERROR(_xlfn.XLOOKUP($W10&AD$4,braves_19_25!$B:$B&braves_19_25!$C:$C,braves_19_25!$R:$R),0)} -> 0.32182698 | AE10: {=IFERROR(_xlfn.XLOOKUP($W10&AE$4,braves_19_25!$B:$B&braves_19_25!$C:$C,braves_19_25!$R:$R),0)} -> 0.0069459061 | ... AM10: {=IFERROR(_xlfn.XLOOKUP($W10&AM$4,braves_19_25!$B:$B&braves_19_25!$C:$C,braves_19_25!$R:$R),0)} -> 0 | AN10: {=SQRT( MMULT( MMULT( $X10:$AM10, $F$5:$U$20 ), TRANSPOSE($X10:$AM10) ) )} -> 0.6069804
A11: ST | B11: Sweeper | C11: Hbreak | E11: CH | F11: =IF(F$4=$E11,1,IF(_xlfn.XLOOKUP(F$4,$A$4:$A$19,$C$4:$C$19)=_xlfn.XLOOKUP($E11,$A$4:$A$19,$C$4:$C$19),0.7,0)) -> 0 | G11: =IF(G$4=$E11,1,IF(_xlfn.XLOOKUP(G$4,$A$4:$A$19,$C$4:$C$19)=_xlfn.XLOOKUP($E11,$A$4:$A$19,$C$4:$C$19),0.7,0)) -> 0 | H11: =IF(H$4=$E11,1,IF(_xlfn.XLOOKUP(H$4,$A$4:$A$19,$C$4:$C$19)=_xlfn.XLOOKUP($E11,$A$4:$A$19,$C$4:$C$19),0.7,0)) -> 0 | I11: =IF(I$4=$E11,1,IF(_xlfn.XLOOKUP(I$4,$A$4:$A$19,$C$4:$C$19)=_xlfn.XLOOKUP($E11,$A$4:$A$19,$C$4:$C$19),0.7,0)) -> 0 | J11: =IF(J$4=$E11,1,IF(_xlfn.XLOOKUP(J$4,$A$4:$A$19,$C$4:$C$19)=_xlfn.XLOOKUP($E11,$A$4:$A$19,$C$4:$C$19),0.7,0)) -> 0.7 | K11: =IF(K$4=$E11,1,IF(_xlfn.XLOOKUP(K$4,$A$4:$A$19,$C$4:$C$19)=_xlfn.XLOOKUP($E11,$A$4:$A$19,$C$4:$C$19),0.7,0)) -> 0 | L11: =IF(L$4=$E11,1,IF(_xlfn.XLOOKUP(L$4,$A$4:$A$19,$C$4:$C$19)=_xlfn.XLOOKUP($E11,$A$4:$A$19,$C$4:$C$19),0.7,0)) -> 1 | M11: =IF(M$4=$E11,1,IF(_xlfn.XLOOKUP(M$4,$A$4:$A$19,$C$4:$C$19)=_xlfn.XLOOKUP($E11,$A$4:$A$19,$C$4:$C$19),0.7,0)) -> 0 | ... U11: =IF(U$4=$E11,1,IF(_xlfn.XLOOKUP(U$4,$A$4:$A$19,$C$4:$C$19)=_xlfn.XLOOKUP($E11,$A$4:$A$19,$C$4:$C$19),0.7,0)) -> 0 | W11: Minter, A.J. | X11: {=IFERROR(_xlfn.XLOOKUP($W11&X$4,braves_19_25!$B:$B&braves_19_25!$C:$C,braves_19_25!$R:$R),0)} -> 0.45213 | Y11: {=IFERROR(_xlfn.XLOOKUP($W11&Y$4,braves_19_25!$B:$B&braves_19_25!$C:$C,braves_19_25!$R:$R),0)} -> 0 | Z11: {=IFERROR(_xlfn.XLOOKUP($W11&Z$4,braves_19_25!$B:$B&braves_19_25!$C:$C,braves_19_25!$R:$R),0)} -> 0 | AA11: {=IFERROR(_xlfn.XLOOKUP($W11&AA$4,braves_19_25!$B:$B&braves_19_25!$C:$C,braves_19_25!$R:$R),0)} -> 0 | AB11: {=IFERROR(_xlfn.XLOOKUP($W11&AB$4,braves_19_25!$B:$B&braves_19_25!$C:$C,braves_19_25!$R:$R),0)} -> 0 | AC11: {=IFERROR(_xlfn.XLOOKUP($W11&AC$4,braves_19_25!$B:$B&braves_19_25!$C:$C,braves_19_25!$R:$R),0)} -> 0.38801054 | AD11: {=IFERROR(_xlfn.XLOOKUP($W11&AD$4,braves_19_25!$B:$B&braves_19_25!$C:$C,braves_19_25!$R:$R),0)} -> 0.15985946 | AE11: {=IFERROR(_xlfn.XLOOKUP($W11&AE$4,braves_19_25!$B:$B&braves_19_25!$C:$C,braves_19_25!$R:$R),0)} -> 0 | ... AM11: {=IFERROR(_xlfn.XLOOKUP($W11&AM$4,braves_19_25!$B:$B&braves_19_25!$C:$C,braves_19_25!$R:$R),0)} -> 0 | AN11: {=SQRT( MMULT( MMULT( $X11:$AM11, $F$5:$U$20 ), TRANSPOSE($X11:$AM11) ) )} -> 0.79128531
A12: EP | B12: Eephus | C12: Other | E12: ST | F12: =IF(F$4=$E12,1,IF(_xlfn.XLOOKUP(F$4,$A$4:$A$19,$C$4:$C$19)=_xlfn.XLOOKUP($E12,$A$4:$A$19,$C$4:$C$19),0.7,0)) -> 0 | G12: =IF(G$4=$E12,1,IF(_xlfn.XLOOKUP(G$4,$A$4:$A$19,$C$4:$C$19)=_xlfn.XLOOKUP($E12,$A$4:$A$19,$C$4:$C$19),0.7,0)) -> 0 | H12: =IF(H$4=$E12,1,IF(_xlfn.XLOOKUP(H$4,$A$4:$A$19,$C$4:$C$19)=_xlfn.XLOOKUP($E12,$A$4:$A$19,$C$4:$C$19),0.7,0)) -> 0.7 | I12: =IF(I$4=$E12,1,IF(_xlfn.XLOOKUP(I$4,$A$4:$A$19,$C$4:$C$19)=_xlfn.XLOOKUP($E12,$A$4:$A$19,$C$4:$C$19),0.7,0)) -> 0 | J12: =IF(J$4=$E12,1,IF(_xlfn.XLOOKUP(J$4,$A$4:$A$19,$C$4:$C$19)=_xlfn.XLOOKUP($E12,$A$4:$A$19,$C$4:$C$19),0.7,0)) -> 0 | K12: =IF(K$4=$E12,1,IF(_xlfn.XLOOKUP(K$4,$A$4:$A$19,$C$4:$C$19)=_xlfn.XLOOKUP($E12,$A$4:$A$19,$C$4:$C$19),0.7,0)) -> 0 | L12: =IF(L$4=$E12,1,IF(_xlfn.XLOOKUP(L$4,$A$4:$A$19,$C$4:$C$19)=_xlfn.XLOOKUP($E12,$A$4:$A$19,$C$4:$C$19),0.7,0)) -> 0 | M12: =IF(M$4=$E12,1,IF(_xlfn.XLOOKUP(M$4,$A$4:$A$19,$C$4:$C$19)=_xlfn.XLOOKUP($E12,$A$4:$A$19,$C$4:$C$19),0.7,0)) -> 1 | ... U12: =IF(U$4=$E12,1,IF(_xlfn.XLOOKUP(U$4,$A$4:$A$19,$C$4:$C$19)=_xlfn.XLOOKUP($E12,$A$4:$A$19,$C$4:$C$19),0.7,0)) -> 0 | W12: Wright, Kyle | X12: {=IFERROR(_xlfn.XLOOKUP($W12&X$4,braves_19_25!$B:$B&braves_19_25!$C:$C,braves_19_25!$R:$R),0)} -> 0.20491244 | Y12: {=IFERROR(_xlfn.XLOOKUP($W12&Y$4,braves_19_25!$B:$B&braves_19_25!$C:$C,braves_19_25!$R:$R),0)} -> 0.24857858 | Z12: {=IFERROR(_xlfn.XLOOKUP($W12&Z$4,braves_19_25!$B:$B&braves_19_25!$C:$C,braves_19_25!$R:$R),0)} -> 0.11030248 | AA12: {=IFERROR(_xlfn.XLOOKUP($W12&AA$4,braves_19_25!$B:$B&braves_19_25!$C:$C,braves_19_25!$R:$R),0)} -> 0 | AB12: {=IFERROR(_xlfn.XLOOKUP($W12&AB$4,braves_19_25!$B:$B&braves_19_25!$C:$C,braves_19_25!$R:$R),0)} -> 0 | AC12: {=IFERROR(_xlfn.XLOOKUP($W12&AC$4,braves_19_25!$B:$B&braves_19_25!$C:$C,braves_19_25!$R:$R),0)} -> 0 | AD12: {=IFERROR(_xlfn.XLOOKUP($W12&AD$4,braves_19_25!$B:$B&braves_19_25!$C:$C,braves_19_25!$R:$R),0)} -> 0.13236297 | AE12: {=IFERROR(_xlfn.XLOOKUP($W12&AE$4,braves_19_25!$B:$B&braves_19_25!$C:$C,braves_19_25!$R:$R),0)} -> 0 | ... AM12: {=IFERROR(_xlfn.XLOOKUP($W12&AM$4,braves_19_25!$B:$B&braves_19_25!$C:$C,braves_19_25!$R:$R),0)} -> 0 | AN12: {=SQRT( MMULT( MMULT( $X12:$AM12, $F$5:$U$20 ), TRANSPOSE($X12:$AM12) ) )} -> 0.54506833
A13: FA | B13: Unknown | C13: Other | E13: EP | F13: =IF(F$4=$E13,1,IF(_xlfn.XLOOKUP(F$4,$A$4:$A$19,$C$4:$C$19)=_xlfn.XLOOKUP($E13,$A$4:$A$19,$C$4:$C$19),0.7,0)) -> 0 | G13: =IF(G$4=$E13,1,IF(_xlfn.XLOOKUP(G$4,$A$4:$A$19,$C$4:$C$19)=_xlfn.XLOOKUP($E13,$A$4:$A$19,$C$4:$C$19),0.7,0)) -> 0 | H13: =IF(H$4=$E13,1,IF(_xlfn.XLOOKUP(H$4,$A$4:$A$19,$C$4:$C$19)=_xlfn.XLOOKUP($E13,$A$4:$A$19,$C$4:$C$19),0.7,0)) -> 0 | I13: =IF(I$4=$E13,1,IF(_xlfn.XLOOKUP(I$4,$A$4:$A$19,$C$4:$C$19)=_xlfn.XLOOKUP($E13,$A$4:$A$19,$C$4:$C$19),0.7,0)) -> 0 | J13: =IF(J$4=$E13,1,IF(_xlfn.XLOOKUP(J$4,$A$4:$A$19,$C$4:$C$19)=_xlfn.XLOOKUP($E13,$A$4:$A$19,$C$4:$C$19),0.7,0)) -> 0 | K13: =IF(K$4=$E13,1,IF(_xlfn.XLOOKUP(K$4,$A$4:$A$19,$C$4:$C$19)=_xlfn.XLOOKUP($E13,$A$4:$A$19,$C$4:$C$19),0.7,0)) -> 0 | L13: =IF(L$4=$E13,1,IF(_xlfn.XLOOKUP(L$4,$A$4:$A$19,$C$4:$C$19)=_xlfn.XLOOKUP($E13,$A$4:$A$19,$C$4:$C$19),0.7,0)) -> 0 | M13: =IF(M$4=$E13,1,IF(_xlfn.XLOOKUP(M$4,$A$4:$A$19,$C$4:$C$19)=_xlfn.XLOOKUP($E13,$A$4:$A$19,$C$4:$C$19),0.7,0)) -> 0 | ... U13: =IF(U$4=$E13,1,IF(_xlfn.XLOOKUP(U$4,$A$4:$A$19,$C$4:$C$19)=_xlfn.XLOOKUP($E13,$A$4:$A$19,$C$4:$C$19),0.7,0)) -> 0.7 | W13: Schwellenbach, Spencer | X13: {=IFERROR(_xlfn.XLOOKUP($W13&X$4,braves_19_25!$B:$B&braves_19_25!$C:$C,braves_19_25!$R:$R),0)} -> 0.31763006 | Y13: {=IFERROR(_xlfn.XLOOKUP($W13&Y$4,braves_19_25!$B:$B&braves_19_25!$C:$C,braves_19_25!$R:$R),0)} -> 0.084104046 | Z13: {=IFERROR(_xlfn.XLOOKUP($W13&Z$4,braves_19_25!$B:$B&braves_19_25!$C:$C,braves_19_25!$R:$R),0)} -> 0.19075145 | AA13: {=IFERROR(_xlfn.XLOOKUP($W13&AA$4,braves_19_25!$B:$B&braves_19_25!$C:$C,braves_19_25!$R:$R),0)} -> 0.13150289 | AB13: {=IFERROR(_xlfn.XLOOKUP($W13&AB$4,braves_19_25!$B:$B&braves_19_25!$C:$C,braves_19_25!$R:$R),0)} -> 0.13294798 | AC13: {=IFERROR(_xlfn.XLOOKUP($W13&AC$4,braves_19_25!$B:$B&braves_19_25!$C:$C,braves_19_25!$R:$R),0)} -> 0.14306358 | AD13: {=IFERROR(_xlfn.XLOOKUP($W13&AD$4,braves_19_25!$B:$B&braves_19_25!$C:$C,braves_19_25!$R:$R),0)} -> 0 | AE13: {=IFERROR(_xlfn.XLOOKUP($W13&AE$4,braves_19_25!$B:$B&braves_19_25!$C:$C,braves_19_25!$R:$R),0)} -> 0 | ... AM13: {=IFERROR(_xlfn.XLOOKUP($W13&AM$4,braves_19_25!$B:$B&braves_19_25!$C:$C,braves_19_25!$R:$R),0)} -> 0 | AN13: {=SQRT( MMULT( MMULT( $X13:$AM13, $F$5:$U$20 ), TRANSPOSE($X13:$AM13) ) )} -> 0.5636012
A14: CS | B14: Slow Curve | C14: Vbreak | E14: FA | F14: =IF(F$4=$E14,1,IF(_xlfn.XLOOKUP(F$4,$A$4:$A$19,$C$4:$C$19)=_xlfn.XLOOKUP($E14,$A$4:$A$19,$C$4:$C$19),0.7,0)) -> 0 | G14: =IF(G$4=$E14,1,IF(_xlfn.XLOOKUP(G$4,$A$4:$A$19,$C$4:$C$19)=_xlfn.XLOOKUP($E14,$A$4:$A$19,$C$4:$C$19),0.7,0)) -> 0 | H14: =IF(H$4=$E14,1,IF(_xlfn.XLOOKUP(H$4,$A$4:$A$19,$C$4:$C$19)=_xlfn.XLOOKUP($E14,$A$4:$A$19,$C$4:$C$19),0.7,0)) -> 0 | I14: =IF(I$4=$E14,1,IF(_xlfn.XLOOKUP(I$4,$A$4:$A$19,$C$4:$C$19)=_xlfn.XLOOKUP($E14,$A$4:$A$19,$C$4:$C$19),0.7,0)) -> 0 | J14: =IF(J$4=$E14,1,IF(_xlfn.XLOOKUP(J$4,$A$4:$A$19,$C$4:$C$19)=_xlfn.XLOOKUP($E14,$A$4:$A$19,$C$4:$C$19),0.7,0)) -> 0 | K14: =IF(K$4=$E14,1,IF(_xlfn.XLOOKUP(K$4,$A$4:$A$19,$C$4:$C$19)=_xlfn.XLOOKUP($E14,$A$4:$A$19,$C$4:$C$19),0.7,0)) -> 0 | L14: =IF(L$4=$E14,1,IF(_xlfn.XLOOKUP(L$4,$A$4:$A$19,$C$4:$C$19)=_xlfn.XLOOKUP($E14,$A$4:$A$19,$C$4:$C$19),0.7,0)) -> 0 | M14: =IF(M$4=$E14,1,IF(_xlfn.XLOOKUP(M$4,$A$4:$A$19,$C$4:$C$19)=_xlfn.XLOOKUP($E14,$A$4:$A$19,$C$4:$C$19),0.7,0)) -> 0 | ... U14: =IF(U$4=$E14,1,IF(_xlfn.XLOOKUP(U$4,$A$4:$A$19,$C$4:$C$19)=_xlfn.XLOOKUP($E14,$A$4:$A$19,$C$4:$C$19),0.7,0)) -> 0.7 | W14: Soroka, Michael | X14: {=IFERROR(_xlfn.XLOOKUP($W14&X$4,braves_19_25!$B:$B&braves_19_25!$C:$C,braves_19_25!$R:$R),0)} -> 0.215263 | Y14: {=IFERROR(_xlfn.XLOOKUP($W14&Y$4,braves_19_25!$B:$B&braves_19_25!$C:$C,braves_19_25!$R:$R),0)} -> 0.40255397 | Z14: {=IFERROR(_xlfn.XLOOKUP($W14&Z$4,braves_19_25!$B:$B&braves_19_25!$C:$C,braves_19_25!$R:$R),0)} -> 0.24657951 | AA14: {=IFERROR(_xlfn.XLOOKUP($W14&AA$4,braves_19_25!$B:$B&braves_19_25!$C:$C,braves_19_25!$R:$R),0)} -> 0 | AB14: {=IFERROR(_xlfn.XLOOKUP($W14&AB$4,braves_19_25!$B:$B&braves_19_25!$C:$C,braves_19_25!$R:$R),0)} -> 0 | AC14: {=IFERROR(_xlfn.XLOOKUP($W14&AC$4,braves_19_25!$B:$B&braves_19_25!$C:$C,braves_19_25!$R:$R),0)} -> 0 | AD14: {=IFERROR(_xlfn.XLOOKUP($W14&AD$4,braves_19_25!$B:$B&braves_19_25!$C:$C,braves_19_25!$R:$R),0)} -> 0.13317118 | AE14: {=IFERROR(_xlfn.XLOOKUP($W14&AE$4,braves_19_25!$B:$B&braves_19_25!$C:$C,braves_19_25!$R:$R),0)} -> 0 | ... AM14: {=IFERROR(_xlfn.XLOOKUP($W14&AM$4,braves_19_25!$B:$B&braves_19_25!$C:$C,braves_19_25!$R:$R),0)} -> 0 | AN14: {=SQRT( MMULT( MMULT( $X14:$AM14, $F$5:$U$20 ), TRANSPOSE($X14:$AM14) ) )} -> 0.63959864
A15: SV | B15: Slurve | C15: Hbreak | E15: CS | F15: =IF(F$4=$E15,1,IF(_xlfn.XLOOKUP(F$4,$A$4:$A$19,$C$4:$C$19)=_xlfn.XLOOKUP($E15,$A$4:$A$19,$C$4:$C$19),0.7,0)) -> 0 | G15: =IF(G$4=$E15,1,IF(_xlfn.XLOOKUP(G$4,$A$4:$A$19,$C$4:$C$19)=_xlfn.XLOOKUP($E15,$A$4:$A$19,$C$4:$C$19),0.7,0)) -> 0 | H15: =IF(H$4=$E15,1,IF(_xlfn.XLOOKUP(H$4,$A$4:$A$19,$C$4:$C$19)=_xlfn.XLOOKUP($E15,$A$4:$A$19,$C$4:$C$19),0.7,0)) -> 0 | I15: =IF(I$4=$E15,1,IF(_xlfn.XLOOKUP(I$4,$A$4:$A$19,$C$4:$C$19)=_xlfn.XLOOKUP($E15,$A$4:$A$19,$C$4:$C$19),0.7,0)) -> 0.7 | J15: =IF(J$4=$E15,1,IF(_xlfn.XLOOKUP(J$4,$A$4:$A$19,$C$4:$C$19)=_xlfn.XLOOKUP($E15,$A$4:$A$19,$C$4:$C$19),0.7,0)) -> 0 | K15: =IF(K$4=$E15,1,IF(_xlfn.XLOOKUP(K$4,$A$4:$A$19,$C$4:$C$19)=_xlfn.XLOOKUP($E15,$A$4:$A$19,$C$4:$C$19),0.7,0)) -> 0 | L15: =IF(L$4=$E15,1,IF(_xlfn.XLOOKUP(L$4,$A$4:$A$19,$C$4:$C$19)=_xlfn.XLOOKUP($E15,$A$4:$A$19,$C$4:$C$19),0.7,0)) -> 0 | M15: =IF(M$4=$E15,1,IF(_xlfn.XLOOKUP(M$4,$A$4:$A$19,$C$4:$C$19)=_xlfn.XLOOKUP($E15,$A$4:$A$19,$C$4:$C$19),0.7,0)) -> 0 | ... U15: =IF(U$4=$E15,1,IF(_xlfn.XLOOKUP(U$4,$A$4:$A$19,$C$4:$C$19)=_xlfn.XLOOKUP($E15,$A$4:$A$19,$C$4:$C$19),0.7,0)) -> 0 | W15: Chavez, Jesse | X15: {=IFERROR(_xlfn.XLOOKUP($W15&X$4,braves_19_25!$B:$B&braves_19_25!$C:$C,braves_19_25!$R:$R),0)} -> 0.0065359477 | Y15: {=IFERROR(_xlfn.XLOOKUP($W15&Y$4,braves_19_25!$B:$B&braves_19_25!$C:$C,braves_19_25!$R:$R),0)} -> 0.28695923 | Z15: {=IFERROR(_xlfn.XLOOKUP($W15&Z$4,braves_19_25!$B:$B&braves_19_25!$C:$C,braves_19_25!$R:$R),0)} -> 0.020230314 | AA15: {=IFERROR(_xlfn.XLOOKUP($W15&AA$4,braves_19_25!$B:$B&braves_19_25!$C:$C,braves_19_25!$R:$R),0)} -> 0.040149393 | AB15: {=IFERROR(_xlfn.XLOOKUP($W15&AB$4,braves_19_25!$B:$B&braves_19_25!$C:$C,braves_19_25!$R:$R),0)} -> 0 | AC15: {=IFERROR(_xlfn.XLOOKUP($W15&AC$4,braves_19_25!$B:$B&braves_19_25!$C:$C,braves_19_25!$R:$R),0)} -> 0.51260504 | AD15: {=IFERROR(_xlfn.XLOOKUP($W15&AD$4,braves_19_25!$B:$B&braves_19_25!$C:$C,braves_19_25!$R:$R),0)} -> 0.13320884 | AE15: {=IFERROR(_xlfn.XLOOKUP($W15&AE$4,braves_19_25!$B:$B&braves_19_25!$C:$C,braves_19_25!$R:$R),0)} -> 0 | ... AM15: {=IFERROR(_xlfn.XLOOKUP($W15&AM$4,braves_19_25!$B:$B&braves_19_25!$C:$C,braves_19_25!$R:$R),0)} -> 0 | AN15: {=SQRT( MMULT( MMULT( $X15:$AM15, $F$5:$U$20 ), TRANSPOSE($X15:$AM15) ) )} -> 0.76037478
A16: KC | B16: Knuckle Curve | C16: Vbreak | E16: SV | F16: =IF(F$4=$E16,1,IF(_xlfn.XLOOKUP(F$4,$A$4:$A$19,$C$4:$C$19)=_xlfn.XLOOKUP($E16,$A$4:$A$19,$C$4:$C$19),0.7,0)) -> 0 | G16: =IF(G$4=$E16,1,IF(_xlfn.XLOOKUP(G$4,$A$4:$A$19,$C$4:$C$19)=_xlfn.XLOOKUP($E16,$A$4:$A$19,$C$4:$C$19),0.7,0)) -> 0 | H16: =IF(H$4=$E16,1,IF(_xlfn.XLOOKUP(H$4,$A$4:$A$19,$C$4:$C$19)=_xlfn.XLOOKUP($E16,$A$4:$A$19,$C$4:$C$19),0.7,0)) -> 0.7 | I16: =IF(I$4=$E16,1,IF(_xlfn.XLOOKUP(I$4,$A$4:$A$19,$C$4:$C$19)=_xlfn.XLOOKUP($E16,$A$4:$A$19,$C$4:$C$19),0.7,0)) -> 0 | J16: =IF(J$4=$E16,1,IF(_xlfn.XLOOKUP(J$4,$A$4:$A$19,$C$4:$C$19)=_xlfn.XLOOKUP($E16,$A$4:$A$19,$C$4:$C$19),0.7,0)) -> 0 | K16: =IF(K$4=$E16,1,IF(_xlfn.XLOOKUP(K$4,$A$4:$A$19,$C$4:$C$19)=_xlfn.XLOOKUP($E16,$A$4:$A$19,$C$4:$C$19),0.7,0)) -> 0 | L16: =IF(L$4=$E16,1,IF(_xlfn.XLOOKUP(L$4,$A$4:$A$19,$C$4:$C$19)=_xlfn.XLOOKUP($E16,$A$4:$A$19,$C$4:$C$19),0.7,0)) -> 0 | M16: =IF(M$4=$E16,1,IF(_xlfn.XLOOKUP(M$4,$A$4:$A$19,$C$4:$C$19)=_xlfn.XLOOKUP($E16,$A$4:$A$19,$C$4:$C$19),0.7,0)) -> 0.7 | ... U16: =IF(U$4=$E16,1,IF(_xlfn.XLOOKUP(U$4,$A$4:$A$19,$C$4:$C$19)=_xlfn.XLOOKUP($E16,$A$4:$A$19,$C$4:$C$19),0.7,0)) -> 0 | W16: Iglesias, Raisel | X16: {=IFERROR(_xlfn.XLOOKUP($W16&X$4,braves_19_25!$B:$B&braves_19_25!$C:$C,braves_19_25!$R:$R),0)} -> 0.3510873 | Y16: {=IFERROR(_xlfn.XLOOKUP($W16&Y$4,braves_19_25!$B:$B&braves_19_25!$C:$C,braves_19_25!$R:$R),0)} -> 0.18373779 | Z16: {=IFERROR(_xlfn.XLOOKUP($W16&Z$4,braves_19_25!$B:$B&braves_19_25!$C:$C,braves_19_25!$R:$R),0)} -> 0.15537346 | AA16: {=IFERROR(_xlfn.XLOOKUP($W16&AA$4,braves_19_25!$B:$B&braves_19_25!$C:$C,braves_19_25!$R:$R),0)} -> 0 | AB16: {=IFERROR(_xlfn.XLOOKUP($W16&AB$4,braves_19_25!$B:$B&braves_19_25!$C:$C,braves_19_25!$R:$R),0)} -> 0 | AC16: {=IFERROR(_xlfn.XLOOKUP($W16&AC$4,braves_19_25!$B:$B&braves_19_25!$C:$C,braves_19_25!$R:$R),0)} -> 0 | AD16: {=IFERROR(_xlfn.XLOOKUP($W16&AD$4,braves_19_25!$B:$B&braves_19_25!$C:$C,braves_19_25!$R:$R),0)} -> 0.30980145 | AE16: {=IFERROR(_xlfn.XLOOKUP($W16&AE$4,braves_19_25!$B:$B&braves_19_25!$C:$C,braves_19_25!$R:$R),0)} -> 0 | ... AM16: {=IFERROR(_xlfn.XLOOKUP($W16&AM$4,braves_19_25!$B:$B&braves_19_25!$C:$C,braves_19_25!$R:$R),0)} -> 0 | AN16: {=SQRT( MMULT( MMULT( $X16:$AM16, $F$5:$U$20 ), TRANSPOSE($X16:$AM16) ) )} -> 0.6061773
A17: FO | B17: Forkball | C17: Offspeed | E17: KC | F17: =IF(F$4=$E17,1,IF(_xlfn.XLOOKUP(F$4,$A$4:$A$19,$C$4:$C$19)=_xlfn.XLOOKUP($E17,$A$4:$A$19,$C$4:$C$19),0.7,0)) -> 0 | G17: =IF(G$4=$E17,1,IF(_xlfn.XLOOKUP(G$4,$A$4:$A$19,$C$4:$C$19)=_xlfn.XLOOKUP($E17,$A$4:$A$19,$C$4:$C$19),0.7,0)) -> 0 | H17: =IF(H$4=$E17,1,IF(_xlfn.XLOOKUP(H$4,$A$4:$A$19,$C$4:$C$19)=_xlfn.XLOOKUP($E17,$A$4:$A$19,$C$4:$C$19),0.7,0)) -> 0 | I17: =IF(I$4=$E17,1,IF(_xlfn.XLOOKUP(I$4,$A$4:$A$19,$C$4:$C$19)=_xlfn.XLOOKUP($E17,$A$4:$A$19,$C$4:$C$19),0.7,0)) -> 0.7 | J17: =IF(J$4=$E17,1,IF(_xlfn.XLOOKUP(J$4,$A$4:$A$19,$C$4:$C$19)=_xlfn.XLOOKUP($E17,$A$4:$A$19,$C$4:$C$19),0.7,0)) -> 0 | K17: =IF(K$4=$E17,1,IF(_xlfn.XLOOKUP(K$4,$A$4:$A$19,$C$4:$C$19)=_xlfn.XLOOKUP($E17,$A$4:$A$19,$C$4:$C$19),0.7,0)) -> 0 | L17: =IF(L$4=$E17,1,IF(_xlfn.XLOOKUP(L$4,$A$4:$A$19,$C$4:$C$19)=_xlfn.XLOOKUP($E17,$A$4:$A$19,$C$4:$C$19),0.7,0)) -> 0 | M17: =IF(M$4=$E17,1,IF(_xlfn.XLOOKUP(M$4,$A$4:$A$19,$C$4:$C$19)=_xlfn.XLOOKUP($E17,$A$4:$A$19,$C$4:$C$19),0.7,0)) -> 0 | ... U17: =IF(U$4=$E17,1,IF(_xlfn.XLOOKUP(U$4,$A$4:$A$19,$C$4:$C$19)=_xlfn.XLOOKUP($E17,$A$4:$A$19,$C$4:$C$19),0.7,0)) -> 0 | W17: Jackson, Luke | X17: {=IFERROR(_xlfn.XLOOKUP($W17&X$4,braves_19_25!$B:$B&braves_19_25!$C:$C,braves_19_25!$R:$R),0)} -> 0.36128827 | Y17: {=IFERROR(_xlfn.XLOOKUP($W17&Y$4,braves_19_25!$B:$B&braves_19_25!$C:$C,braves_19_25!$R:$R),0)} -> 0 | Z17: {=IFERROR(_xlfn.XLOOKUP($W17&Z$4,braves_19_25!$B:$B&braves_19_25!$C:$C,braves_19_25!$R:$R),0)} -> 0.50669643 | AA17: {=IFERROR(_xlfn.XLOOKUP($W17&AA$4,braves_19_25!$B:$B&braves_19_25!$C:$C,braves_19_25!$R:$R),0)} -> 0.12882653 | AB17: {=IFERROR(_xlfn.XLOOKUP($W17&AB$4,braves_19_25!$B:$B&braves_19_25!$C:$C,braves_19_25!$R:$R),0)} -> 0 | AC17: {=IFERROR(_xlfn.XLOOKUP($W17&AC$4,braves_19_25!$B:$B&braves_19_25!$C:$C,braves_19_25!$R:$R),0)} -> 0.0031887755 | AD17: {=IFERROR(_xlfn.XLOOKUP($W17&AD$4,braves_19_25!$B:$B&braves_19_25!$C:$C,braves_19_25!$R:$R),0)} -> 0 | AE17: {=IFERROR(_xlfn.XLOOKUP($W17&AE$4,braves_19_25!$B:$B&braves_19_25!$C:$C,braves_19_25!$R:$R),0)} -> 0 | ... AM17: {=IFERROR(_xlfn.XLOOKUP($W17&AM$4,braves_19_25!$B:$B&braves_19_25!$C:$C,braves_19_25!$R:$R),0)} -> 0 | AN17: {=SQRT( MMULT( MMULT( $X17:$AM17, $F$5:$U$20 ), TRANSPOSE($X17:$AM17) ) )} -> 0.63678082
... A19: KN | B19: Knuckleball | C19: Other | E19: SC | F19: =IF(F$4=$E19,1,IF(_xlfn.XLOOKUP(F$4,$A$4:$A$19,$C$4:$C$19)=_xlfn.XLOOKUP($E19,$A$4:$A$19,$C$4:$C$19),0.7,0)) -> 0 | G19: =IF(G$4=$E19,1,IF(_xlfn.XLOOKUP(G$4,$A$4:$A$19,$C$4:$C$19)=_xlfn.XLOOKUP($E19,$A$4:$A$19,$C$4:$C$19),0.7,0)) -> 0 | H19: =IF(H$4=$E19,1,IF(_xlfn.XLOOKUP(H$4,$A$4:$A$19,$C$4:$C$19)=_xlfn.XLOOKUP($E19,$A$4:$A$19,$C$4:$C$19),0.7,0)) -> 0 | I19: =IF(I$4=$E19,1,IF(_xlfn.XLOOKUP(I$4,$A$4:$A$19,$C$4:$C$19)=_xlfn.XLOOKUP($E19,$A$4:$A$19,$C$4:$C$19),0.7,0)) -> 0 | J19: =IF(J$4=$E19,1,IF(_xlfn.XLOOKUP(J$4,$A$4:$A$19,$C$4:$C$19)=_xlfn.XLOOKUP($E19,$A$4:$A$19,$C$4:$C$19),0.7,0)) -> 0.7 | K19: =IF(K$4=$E19,1,IF(_xlfn.XLOOKUP(K$4,$A$4:$A$19,$C$4:$C$19)=_xlfn.XLOOKUP($E19,$A$4:$A$19,$C$4:$C$19),0.7,0)) -> 0 | L19: =IF(L$4=$E19,1,IF(_xlfn.XLOOKUP(L$4,$A$4:$A$19,$C$4:$C$19)=_xlfn.XLOOKUP($E19,$A$4:$A$19,$C$4:$C$19),0.7,0)) -> 0.7 | M19: =IF(M$4=$E19,1,IF(_xlfn.XLOOKUP(M$4,$A$4:$A$19,$C$4:$C$19)=_xlfn.XLOOKUP($E19,$A$4:$A$19,$C$4:$C$19),0.7,0)) -> 0 | ... U19: =IF(U$4=$E19,1,IF(_xlfn.XLOOKUP(U$4,$A$4:$A$19,$C$4:$C$19)=_xlfn.XLOOKUP($E19,$A$4:$A$19,$C$4:$C$19),0.7,0)) -> 0 | W19: Holmes, Grant | X19: {=IFERROR(_xlfn.XLOOKUP($W19&X$4,braves_19_25!$B:$B&braves_19_25!$C:$C,braves_19_25!$R:$R),0)} -> 0.34236948 | Y19: {=IFERROR(_xlfn.XLOOKUP($W19&Y$4,braves_19_25!$B:$B&braves_19_25!$C:$C,braves_19_25!$R:$R),0)} -> 0.00066934404 | Z19: {=IFERROR(_xlfn.XLOOKUP($W19&Z$4,braves_19_25!$B:$B&braves_19_25!$C:$C,braves_19_25!$R:$R),0)} -> 0.3457162 | AA19: {=IFERROR(_xlfn.XLOOKUP($W19&AA$4,braves_19_25!$B:$B&braves_19_25!$C:$C,braves_19_25!$R:$R),0)} -> 0.17202142 | AB19: {=IFERROR(_xlfn.XLOOKUP($W19&AB$4,braves_19_25!$B:$B&braves_19_25!$C:$C,braves_19_25!$R:$R),0)} -> 0 | AC19: {=IFERROR(_xlfn.XLOOKUP($W19&AC$4,braves_19_25!$B:$B&braves_19_25!$C:$C,braves_19_25!$R:$R),0)} -> 0.12751004 | AD19: {=IFERROR(_xlfn.XLOOKUP($W19&AD$4,braves_19_25!$B:$B&braves_19_25!$C:$C,braves_19_25!$R:$R),0)} -> 0.011713521 | AE19: {=IFERROR(_xlfn.XLOOKUP($W19&AE$4,braves_19_25!$B:$B&braves_19_25!$C:$C,braves_19_25!$R:$R),0)} -> 0 | ... AM19: {=IFERROR(_xlfn.XLOOKUP($W19&AM$4,braves_19_25!$B:$B&braves_19_25!$C:$C,braves_19_25!$R:$R),0)} -> 0 | AN19: {=SQRT( MMULT( MMULT( $X19:$AM19, $F$5:$U$20 ), TRANSPOSE($X19:$AM19) ) )} -> 0.58675588
E20: KN | F20: =IF(F$4=$E20,1,IF(_xlfn.XLOOKUP(F$4,$A$4:$A$19,$C$4:$C$19)=_xlfn.XLOOKUP($E20,$A$4:$A$19,$C$4:$C$19),0.7,0)) -> 0 | G20: =IF(G$4=$E20,1,IF(_xlfn.XLOOKUP(G$4,$A$4:$A$19,$C$4:$C$19)=_xlfn.XLOOKUP($E20,$A$4:$A$19,$C$4:$C$19),0.7,0)) -> 0 | H20: =IF(H$4=$E20,1,IF(_xlfn.XLOOKUP(H$4,$A$4:$A$19,$C$4:$C$19)=_xlfn.XLOOKUP($E20,$A$4:$A$19,$C$4:$C$19),0.7,0)) -> 0 | I20: =IF(I$4=$E20,1,IF(_xlfn.XLOOKUP(I$4,$A$4:$A$19,$C$4:$C$19)=_xlfn.XLOOKUP($E20,$A$4:$A$19,$C$4:$C$19),0.7,0)) -> 0 | J20: =IF(J$4=$E20,1,IF(_xlfn.XLOOKUP(J$4,$A$4:$A$19,$C$4:$C$19)=_xlfn.XLOOKUP($E20,$A$4:$A$19,$C$4:$C$19),0.7,0)) -> 0 | K20: =IF(K$4=$E20,1,IF(_xlfn.XLOOKUP(K$4,$A$4:$A$19,$C$4:$C$19)=_xlfn.XLOOKUP($E20,$A$4:$A$19,$C$4:$C$19),0.7,0)) -> 0 | L20: =IF(L$4=$E20,1,IF(_xlfn.XLOOKUP(L$4,$A$4:$A$19,$C$4:$C$19)=_xlfn.XLOOKUP($E20,$A$4:$A$19,$C$4:$C$19),0.7,0)) -> 0 | M20: =IF(M$4=$E20,1,IF(_xlfn.XLOOKUP(M$4,$A$4:$A$19,$C$4:$C$19)=_xlfn.XLOOKUP($E20,$A$4:$A$19,$C$4:$C$19),0.7,0)) -> 0 | ... U20: =IF(U$4=$E20,1,IF(_xlfn.XLOOKUP(U$4,$A$4:$A$19,$C$4:$C$19)=_xlfn.XLOOKUP($E20,$A$4:$A$19,$C$4:$C$19),0.7,0)) -> 1 | W20: Tomlin, Josh | X20: {=IFERROR(_xlfn.XLOOKUP($W20&X$4,braves_19_25!$B:$B&braves_19_25!$C:$C,braves_19_25!$R:$R),0)} -> 0.2278682 | Y20: {=IFERROR(_xlfn.XLOOKUP($W20&Y$4,braves_19_25!$B:$B&braves_19_25!$C:$C,braves_19_25!$R:$R),0)} -> 0.026994839 | Z20: {=IFERROR(_xlfn.XLOOKUP($W20&Z$4,braves_19_25!$B:$B&braves_19_25!$C:$C,braves_19_25!$R:$R),0)} -> 0 | AA20: {=IFERROR(_xlfn.XLOOKUP($W20&AA$4,braves_19_25!$B:$B&braves_19_25!$C:$C,braves_19_25!$R:$R),0)} -> 0.2302501 | AB20: {=IFERROR(_xlfn.XLOOKUP($W20&AB$4,braves_19_25!$B:$B&braves_19_25!$C:$C,braves_19_25!$R:$R),0)} -> 0 | AC20: {=IFERROR(_xlfn.XLOOKUP($W20&AC$4,braves_19_25!$B:$B&braves_19_25!$C:$C,braves_19_25!$R:$R),0)} -> 0.46248511 | AD20: {=IFERROR(_xlfn.XLOOKUP($W20&AD$4,braves_19_25!$B:$B&braves_19_25!$C:$C,braves_19_25!$R:$R),0)} -> 0.052401747 | AE20: {=IFERROR(_xlfn.XLOOKUP($W20&AE$4,braves_19_25!$B:$B&braves_19_25!$C:$C,braves_19_25!$R:$R),0)} -> 0 | ... AM20: {=IFERROR(_xlfn.XLOOKUP($W20&AM$4,braves_19_25!$B:$B&braves_19_25!$C:$C,braves_19_25!$R:$R),0)} -> 0 | AN20: {=SQRT( MMULT( MMULT( $X20:$AM20, $F$5:$U$20 ), TRANSPOSE($X20:$AM20) ) )} -> 0.70422755
W21: Matzek, Tyler | X21: {=IFERROR(_xlfn.XLOOKUP($W21&X$4,braves_19_25!$B:$B&braves_19_25!$C:$C,braves_19_25!$R:$R),0)} -> 0.70286885 | Y21: {=IFERROR(_xlfn.XLOOKUP($W21&Y$4,braves_19_25!$B:$B&braves_19_25!$C:$C,braves_19_25!$R:$R),0)} -> 0.0016393443 | Z21: {=IFERROR(_xlfn.XLOOKUP($W21&Z$4,braves_19_25!$B:$B&braves_19_25!$C:$C,braves_19_25!$R:$R),0)} -> 0.25122951 | AA21: {=IFERROR(_xlfn.XLOOKUP($W21&AA$4,braves_19_25!$B:$B&braves_19_25!$C:$C,braves_19_25!$R:$R),0)} -> 0.025 | AB21: {=IFERROR(_xlfn.XLOOKUP($W21&AB$4,braves_19_25!$B:$B&braves_19_25!$C:$C,braves_19_25!$R:$R),0)} -> 0 | AC21: {=IFERROR(_xlfn.XLOOKUP($W21&AC$4,braves_19_25!$B:$B&braves_19_25!$C:$C,braves_19_25!$R:$R),0)} -> 0.019262295 | AD21: {=IFERROR(_xlfn.XLOOKUP($W21&AD$4,braves_19_25!$B:$B&braves_19_25!$C:$C,braves_19_25!$R:$R),0)} -> 0 | AE21: {=IFERROR(_xlfn.XLOOKUP($W21&AE$4,braves_19_25!$B:$B&braves_19_25!$C:$C,braves_19_25!$R:$R),0)} -> 0 | ... AM21: {=IFERROR(_xlfn.XLOOKUP($W21&AM$4,braves_19_25!$B:$B&braves_19_25!$C:$C,braves_19_25!$R:$R),0)} -> 0 | AN21: {=SQRT( MMULT( MMULT( $X21:$AM21, $F$5:$U$20 ), TRANSPOSE($X21:$AM21) ) )} -> 0.76075711
W22: Newcomb, Sean | X22: {=IFERROR(_xlfn.XLOOKUP($W22&X$4,braves_19_25!$B:$B&braves_19_25!$C:$C,braves_19_25!$R:$R),0)} -> 0.61217237 | Y22: {=IFERROR(_xlfn.XLOOKUP($W22&Y$4,braves_19_25!$B:$B&braves_19_25!$C:$C,braves_19_25!$R:$R),0)} -> 0.000444247 | Z22: {=IFERROR(_xlfn.XLOOKUP($W22&Z$4,braves_19_25!$B:$B&braves_19_25!$C:$C,braves_19_25!$R:$R),0)} -> 0.05330964 | AA22: {=IFERROR(_xlfn.XLOOKUP($W22&AA$4,braves_19_25!$B:$B&braves_19_25!$C:$C,braves_19_25!$R:$R),0)} -> 0.17858729 | AB22: {=IFERROR(_xlfn.XLOOKUP($W22&AB$4,braves_19_25!$B:$B&braves_19_25!$C:$C,braves_19_25!$R:$R),0)} -> 0 | AC22: {=IFERROR(_xlfn.XLOOKUP($W22&AC$4,braves_19_25!$B:$B&braves_19_25!$C:$C,braves_19_25!$R:$R),0)} -> 0.086628165 | AD22: {=IFERROR(_xlfn.XLOOKUP($W22&AD$4,braves_19_25!$B:$B&braves_19_25!$C:$C,braves_19_25!$R:$R),0)} -> 0.067081297 | AE22: {=IFERROR(_xlfn.XLOOKUP($W22&AE$4,braves_19_25!$B:$B&braves_19_25!$C:$C,braves_19_25!$R:$R),0)} -> 0 | ... AM22: {=IFERROR(_xlfn.XLOOKUP($W22&AM$4,braves_19_25!$B:$B&braves_19_25!$C:$C,braves_19_25!$R:$R),0)} -> 0 | AN22: {=SQRT( MMULT( MMULT( $X22:$AM22, $F$5:$U$20 ), TRANSPOSE($X22:$AM22) ) )} -> 0.70449216
A23: Most/Least Similar | W23: Johnson, Pierce | X23: {=IFERROR(_xlfn.XLOOKUP($W23&X$4,braves_19_25!$B:$B&braves_19_25!$C:$C,braves_19_25!$R:$R),0)} -> 0.237646 | Y23: {=IFERROR(_xlfn.XLOOKUP($W23&Y$4,braves_19_25!$B:$B&braves_19_25!$C:$C,braves_19_25!$R:$R),0)} -> 0 | Z23: {=IFERROR(_xlfn.XLOOKUP($W23&Z$4,braves_19_25!$B:$B&braves_19_25!$C:$C,braves_19_25!$R:$R),0)} -> 0.0062893082 | AA23: {=IFERROR(_xlfn.XLOOKUP($W23&AA$4,braves_19_25!$B:$B&braves_19_25!$C:$C,braves_19_25!$R:$R),0)} -> 0.7178796 | AB23: {=IFERROR(_xlfn.XLOOKUP($W23&AB$4,braves_19_25!$B:$B&braves_19_25!$C:$C,braves_19_25!$R:$R),0)} -> 0 | AC23: {=IFERROR(_xlfn.XLOOKUP($W23&AC$4,braves_19_25!$B:$B&braves_19_25!$C:$C,braves_19_25!$R:$R),0)} -> 0.038185085 | AD23: {=IFERROR(_xlfn.XLOOKUP($W23&AD$4,braves_19_25!$B:$B&braves_19_25!$C:$C,braves_19_25!$R:$R),0)} -> 0 | AE23: {=IFERROR(_xlfn.XLOOKUP($W23&AE$4,braves_19_25!$B:$B&braves_19_25!$C:$C,braves_19_25!$R:$R),0)} -> 0 | ... AM23: {=IFERROR(_xlfn.XLOOKUP($W23&AM$4,braves_19_25!$B:$B&braves_19_25!$C:$C,braves_19_25!$R:$R),0)} -> 0 | AN23: {=SQRT( MMULT( MMULT( $X23:$AM23, $F$5:$U$20 ), TRANSPOSE($X23:$AM23) ) )} -> 0.76552515
W24: López, Reynaldo | X24: {=IFERROR(_xlfn.XLOOKUP($W24&X$4,braves_19_25!$B:$B&braves_19_25!$C:$C,braves_19_25!$R:$R),0)} -> 0.55036298 | Y24: {=IFERROR(_xlfn.XLOOKUP($W24&Y$4,braves_19_25!$B:$B&braves_19_25!$C:$C,braves_19_25!$R:$R),0)} -> 0 | Z24: {=IFERROR(_xlfn.XLOOKUP($W24&Z$4,braves_19_25!$B:$B&braves_19_25!$C:$C,braves_19_25!$R:$R),0)} -> 0.29537205 | AA24: {=IFERROR(_xlfn.XLOOKUP($W24&AA$4,braves_19_25!$B:$B&braves_19_25!$C:$C,braves_19_25!$R:$R),0)} -> 0.11615245 | AB24: {=IFERROR(_xlfn.XLOOKUP($W24&AB$4,braves_19_25!$B:$B&braves_19_25!$C:$C,braves_19_25!$R:$R),0)} -> 0 | AC24: {=IFERROR(_xlfn.XLOOKUP($W24&AC$4,braves_19_25!$B:$B&braves_19_25!$C:$C,braves_19_25!$R:$R),0)} -> 0 | AD24: {=IFERROR(_xlfn.XLOOKUP($W24&AD$4,braves_19_25!$B:$B&braves_19_25!$C:$C,braves_19_25!$R:$R),0)} -> 0.038112523 | AE24: {=IFERROR(_xlfn.XLOOKUP($W24&AE$4,braves_19_25!$B:$B&braves_19_25!$C:$C,braves_19_25!$R:$R),0)} -> 0 | ... AM24: {=IFERROR(_xlfn.XLOOKUP($W24&AM$4,braves_19_25!$B:$B&braves_19_25!$C:$C,braves_19_25!$R:$R),0)} -> 0 | AN24: {=SQRT( MMULT( MMULT( $X24:$AM24, $F$5:$U$20 ), TRANSPOSE($X24:$AM24) ) )} -> 0.63646525
A25: {=_xlfn.UNIQUE(braves_19_25__2[player_name])} -> Fried, Max | W25: Smyly, Drew | X25: {=IFERROR(_xlfn.XLOOKUP($W25&X$4,braves_19_25!$B:$B&braves_19_25!$C:$C,braves_19_25!$R:$R),0)} -> 0 | Y25: {=IFERROR(_xlfn.XLOOKUP($W25&Y$4,braves_19_25!$B:$B&braves_19_25!$C:$C,braves_19_25!$R:$R),0)} -> 0.46538821 | Z25: {=IFERROR(_xlfn.XLOOKUP($W25&Z$4,braves_19_25!$B:$B&braves_19_25!$C:$C,braves_19_25!$R:$R),0)} -> 0 | AA25: {=IFERROR(_xlfn.XLOOKUP($W25&AA$4,braves_19_25!$B:$B&braves_19_25!$C:$C,braves_19_25!$R:$R),0)} -> 0 | AB25: {=IFERROR(_xlfn.XLOOKUP($W25&AB$4,braves_19_25!$B:$B&braves_19_25!$C:$C,braves_19_25!$R:$R),0)} -> 0 | AC25: {=IFERROR(_xlfn.XLOOKUP($W25&AC$4,braves_19_25!$B:$B&braves_19_25!$C:$C,braves_19_25!$R:$R),0)} -> 0.1150608 | AD25: {=IFERROR(_xlfn.XLOOKUP($W25&AD$4,braves_19_25!$B:$B&braves_19_25!$C:$C,braves_19_25!$R:$R),0)} -> 0 | AE25: {=IFERROR(_xlfn.XLOOKUP($W25&AE$4,braves_19_25!$B:$B&braves_19_25!$C:$C,braves_19_25!$R:$R),0)} -> 0 | ... AM25: {=IFERROR(_xlfn.XLOOKUP($W25&AM$4,braves_19_25!$B:$B&braves_19_25!$C:$C,braves_19_25!$R:$R),0)} -> 0 | AN25: {=SQRT( MMULT( MMULT( $X25:$AM25, $F$5:$U$20 ), TRANSPOSE($X25:$AM25) ) )} -> 0.69340848
A26: Morton, Charlie | W26: McHugh, Collin | X26: {=IFERROR(_xlfn.XLOOKUP($W26&X$4,braves_19_25!$B:$B&braves_19_25!$C:$C,braves_19_25!$R:$R),0)} -> 0.023288973 | Y26: {=IFERROR(_xlfn.XLOOKUP($W26&Y$4,braves_19_25!$B:$B&braves_19_25!$C:$C,braves_19_25!$R:$R),0)} -> 0 | Z26: {=IFERROR(_xlfn.XLOOKUP($W26&Z$4,braves_19_25!$B:$B&braves_19_25!$C:$C,braves_19_25!$R:$R),0)} -> 0 | AA26: {=IFERROR(_xlfn.XLOOKUP($W26&AA$4,braves_19_25!$B:$B&braves_19_25!$C:$C,braves_19_25!$R:$R),0)} -> 0.021387833 | AB26: {=IFERROR(_xlfn.XLOOKUP($W26&AB$4,braves_19_25!$B:$B&braves_19_25!$C:$C,braves_19_25!$R:$R),0)} -> 0 | AC26: {=IFERROR(_xlfn.XLOOKUP($W26&AC$4,braves_19_25!$B:$B&braves_19_25!$C:$C,braves_19_25!$R:$R),0)} -> 0.46673004 | AD26: {=IFERROR(_xlfn.XLOOKUP($W26&AD$4,braves_19_25!$B:$B&braves_19_25!$C:$C,braves_19_25!$R:$R),0)} -> 0.0019011407 | AE26: {=IFERROR(_xlfn.XLOOKUP($W26&AE$4,braves_19_25!$B:$B&braves_19_25!$C:$C,braves_19_25!$R:$R),0)} -> 0.48098859 | ... AM26: {=IFERROR(_xlfn.XLOOKUP($W26&AM$4,braves_19_25!$B:$B&braves_19_25!$C:$C,braves_19_25!$R:$R),0)} -> 0 | AN26: {=SQRT( MMULT( MMULT( $X26:$AM26, $F$5:$U$20 ), TRANSPOSE($X26:$AM26) ) )} -> 0.68235711
A27: Strider, Spencer | W27: Ynoa, Huascar | X27: {=IFERROR(_xlfn.XLOOKUP($W27&X$4,braves_19_25!$B:$B&braves_19_25!$C:$C,braves_19_25!$R:$R),0)} -> 0.4430622 | Y27: {=IFERROR(_xlfn.XLOOKUP($W27&Y$4,braves_19_25!$B:$B&braves_19_25!$C:$C,braves_19_25!$R:$R),0)} -> 0.01722488 | Z27: {=IFERROR(_xlfn.XLOOKUP($W27&Z$4,braves_19_25!$B:$B&braves_19_25!$C:$C,braves_19_25!$R:$R),0)} -> 0.46650718 | AA27: {=IFERROR(_xlfn.XLOOKUP($W27&AA$4,braves_19_25!$B:$B&braves_19_25!$C:$C,braves_19_25!$R:$R),0)} -> 0 | AB27: {=IFERROR(_xlfn.XLOOKUP($W27&AB$4,braves_19_25!$B:$B&braves_19_25!$C:$C,braves_19_25!$R:$R),0)} -> 0 | AC27: {=IFERROR(_xlfn.XLOOKUP($W27&AC$4,braves_19_25!$B:$B&braves_19_25!$C:$C,braves_19_25!$R:$R),0)} -> 0 | AD27: {=IFERROR(_xlfn.XLOOKUP($W27&AD$4,braves_19_25!$B:$B&braves_19_25!$C:$C,braves_19_25!$R:$R),0)} -> 0.073205742 | AE27: {=IFERROR(_xlfn.XLOOKUP($W27&AE$4,braves_19_25!$B:$B&braves_19_25!$C:$C,braves_19_25!$R:$R),0)} -> 0 | ... AM27: {=IFERROR(_xlfn.XLOOKUP($W27&AM$4,braves_19_25!$B:$B&braves_19_25!$C:$C,braves_19_25!$R:$R),0)} -> 0 | AN27: {=SQRT( MMULT( MMULT( $X27:$AM27, $F$5:$U$20 ), TRANSPOSE($X27:$AM27) ) )} -> 0.65595214
A28: Elder, Bryce | W28: Toussaint, Touki | X28: {=IFERROR(_xlfn.XLOOKUP($W28&X$4,braves_19_25!$B:$B&braves_19_25!$C:$C,braves_19_25!$R:$R),0)} -> 0.19061303 | Y28: {=IFERROR(_xlfn.XLOOKUP($W28&Y$4,braves_19_25!$B:$B&braves_19_25!$C:$C,braves_19_25!$R:$R),0)} -> 0.29166667 | Z28: {=IFERROR(_xlfn.XLOOKUP($W28&Z$4,braves_19_25!$B:$B&braves_19_25!$C:$C,braves_19_25!$R:$R),0)} -> 0.022509579 | AA28: {=IFERROR(_xlfn.XLOOKUP($W28&AA$4,braves_19_25!$B:$B&braves_19_25!$C:$C,braves_19_25!$R:$R),0)} -> 0.27681992 | AB28: {=IFERROR(_xlfn.XLOOKUP($W28&AB$4,braves_19_25!$B:$B&braves_19_25!$C:$C,braves_19_25!$R:$R),0)} -> 0.2183908 | AC28: {=IFERROR(_xlfn.XLOOKUP($W28&AC$4,braves_19_25!$B:$B&braves_19_25!$C:$C,braves_19_25!$R:$R),0)} -> 0 | AD28: {=IFERROR(_xlfn.XLOOKUP($W28&AD$4,braves_19_25!$B:$B&braves_19_25!$C:$C,braves_19_25!$R:$R),0)} -> 0 | AE28: {=IFERROR(_xlfn.XLOOKUP($W28&AE$4,braves_19_25!$B:$B&braves_19_25!$C:$C,braves_19_25!$R:$R),0)} -> 0 | ... AM28: {=IFERROR(_xlfn.XLOOKUP($W28&AM$4,braves_19_25!$B:$B&braves_19_25!$C:$C,braves_19_25!$R:$R),0)} -> 0 | AN28: {=SQRT( MMULT( MMULT( $X28:$AM28, $F$5:$U$20 ), TRANSPOSE($X28:$AM28) ) )} -> 0.56926876
A29: Sale, Chris | W29: Jiménez, Joe | X29: {=IFERROR(_xlfn.XLOOKUP($W29&X$4,braves_19_25!$B:$B&braves_19_25!$C:$C,braves_19_25!$R:$R),0)} -> 0.53580247 | Y29: {=IFERROR(_xlfn.XLOOKUP($W29&Y$4,braves_19_25!$B:$B&braves_19_25!$C:$C,braves_19_25!$R:$R),0)} -> 0 | Z29: {=IFERROR(_xlfn.XLOOKUP($W29&Z$4,braves_19_25!$B:$B&braves_19_25!$C:$C,braves_19_25!$R:$R),0)} -> 0.40839506 | AA29: {=IFERROR(_xlfn.XLOOKUP($W29&AA$4,braves_19_25!$B:$B&braves_19_25!$C:$C,braves_19_25!$R:$R),0)} -> 0 | AB29: {=IFERROR(_xlfn.XLOOKUP($W29&AB$4,braves_19_25!$B:$B&braves_19_25!$C:$C,braves_19_25!$R:$R),0)} -> 0 | AC29: {=IFERROR(_xlfn.XLOOKUP($W29&AC$4,braves_19_25!$B:$B&braves_19_25!$C:$C,braves_19_25!$R:$R),0)} -> 0 | AD29: {=IFERROR(_xlfn.XLOOKUP($W29&AD$4,braves_19_25!$B:$B&braves_19_25!$C:$C,braves_19_25!$R:$R),0)} -> 0.055308642 | AE29: {=IFERROR(_xlfn.XLOOKUP($W29&AE$4,braves_19_25!$B:$B&braves_19_25!$C:$C,braves_19_25!$R:$R),0)} -> 0 | ... AM29: {=IFERROR(_xlfn.XLOOKUP($W29&AM$4,braves_19_25!$B:$B&braves_19_25!$C:$C,braves_19_25!$R:$R),0)} -> 0 | AN29: {=SQRT( MMULT( MMULT( $X29:$AM29, $F$5:$U$20 ), TRANSPOSE($X29:$AM29) ) )} -> 0.67596587
A30: Anderson, Ian | W30: Smith, Will | X30: {=IFERROR(_xlfn.XLOOKUP($W30&X$4,braves_19_25!$B:$B&braves_19_25!$C:$C,braves_19_25!$R:$R),0)} -> 0.45216516 | Y30: {=IFERROR(_xlfn.XLOOKUP($W30&Y$4,braves_19_25!$B:$B&braves_19_25!$C:$C,braves_19_25!$R:$R),0)} -> 0 | Z30: {=IFERROR(_xlfn.XLOOKUP($W30&Z$4,braves_19_25!$B:$B&braves_19_25!$C:$C,braves_19_25!$R:$R),0)} -> 0.43856999 | AA30: {=IFERROR(_xlfn.XLOOKUP($W30&AA$4,braves_19_25!$B:$B&braves_19_25!$C:$C,braves_19_25!$R:$R),0)} -> 0.10926485 | AB30: {=IFERROR(_xlfn.XLOOKUP($W30&AB$4,braves_19_25!$B:$B&braves_19_25!$C:$C,braves_19_25!$R:$R),0)} -> 0 | AC30: {=IFERROR(_xlfn.XLOOKUP($W30&AC$4,braves_19_25!$B:$B&braves_19_25!$C:$C,braves_19_25!$R:$R),0)} -> 0 | AD30: {=IFERROR(_xlfn.XLOOKUP($W30&AD$4,braves_19_25!$B:$B&braves_19_25!$C:$C,braves_19_25!$R:$R),0)} -> 0 | AE30: {=IFERROR(_xlfn.XLOOKUP($W30&AE$4,braves_19_25!$B:$B&braves_19_25!$C:$C,braves_19_25!$R:$R),0)} -> 0 | ... AM30: {=IFERROR(_xlfn.XLOOKUP($W30&AM$4,braves_19_25!$B:$B&braves_19_25!$C:$C,braves_19_25!$R:$R),0)} -> 0 | AN30: {=SQRT( MMULT( MMULT( $X30:$AM30, $F$5:$U$20 ), TRANSPOSE($X30:$AM30) ) )} -> 0.63932447
A31: Minter, A.J. | W31: Foltynewicz, Mike | X31: {=IFERROR(_xlfn.XLOOKUP($W31&X$4,braves_19_25!$B:$B&braves_19_25!$C:$C,braves_19_25!$R:$R),0)} -> 0.26149132 | Y31: {=IFERROR(_xlfn.XLOOKUP($W31&Y$4,braves_19_25!$B:$B&braves_19_25!$C:$C,braves_19_25!$R:$R),0)} -> 0.25536261 | Z31: {=IFERROR(_xlfn.XLOOKUP($W31&Z$4,braves_19_25!$B:$B&braves_19_25!$C:$C,braves_19_25!$R:$R),0)} -> 0.28600613 | AA31: {=IFERROR(_xlfn.XLOOKUP($W31&AA$4,braves_19_25!$B:$B&braves_19_25!$C:$C,braves_19_25!$R:$R),0)} -> 0.1011236 | AB31: {=IFERROR(_xlfn.XLOOKUP($W31&AB$4,braves_19_25!$B:$B&braves_19_25!$C:$C,braves_19_25!$R:$R),0)} -> 0 | AC31: {=IFERROR(_xlfn.XLOOKUP($W31&AC$4,braves_19_25!$B:$B&braves_19_25!$C:$C,braves_19_25!$R:$R),0)} -> 0 | AD31: {=IFERROR(_xlfn.XLOOKUP($W31&AD$4,braves_19_25!$B:$B&braves_19_25!$C:$C,braves_19_25!$R:$R),0)} -> 0.096016343 | AE31: {=IFERROR(_xlfn.XLOOKUP($W31&AE$4,braves_19_25!$B:$B&braves_19_25!$C:$C,braves_19_25!$R:$R),0)} -> 0 | ... AM31: {=IFERROR(_xlfn.XLOOKUP($W31&AM$4,braves_19_25!$B:$B&braves_19_25!$C:$C,braves_19_25!$R:$R),0)} -> 0 | AN31: {=SQRT( MMULT( MMULT( $X31:$AM31, $F$5:$U$20 ), TRANSPOSE($X31:$AM31) ) )} -> 0.57299001
A32: Wright, Kyle | W32: Bummer, Aaron | X32: {=IFERROR(_xlfn.XLOOKUP($W32&X$4,braves_19_25!$B:$B&braves_19_25!$C:$C,braves_19_25!$R:$R),0)} -> 0.11175236 | Y32: {=IFERROR(_xlfn.XLOOKUP($W32&Y$4,braves_19_25!$B:$B&braves_19_25!$C:$C,braves_19_25!$R:$R),0)} -> 0.37355719 | Z32: {=IFERROR(_xlfn.XLOOKUP($W32&Z$4,braves_19_25!$B:$B&braves_19_25!$C:$C,braves_19_25!$R:$R),0)} -> 0 | AA32: {=IFERROR(_xlfn.XLOOKUP($W32&AA$4,braves_19_25!$B:$B&braves_19_25!$C:$C,braves_19_25!$R:$R),0)} -> 0.18310598 | AB32: {=IFERROR(_xlfn.XLOOKUP($W32&AB$4,braves_19_25!$B:$B&braves_19_25!$C:$C,braves_19_25!$R:$R),0)} -> 0 | AC32: {=IFERROR(_xlfn.XLOOKUP($W32&AC$4,braves_19_25!$B:$B&braves_19_25!$C:$C,braves_19_25!$R:$R),0)} -> 0.026232949 | AD32: {=IFERROR(_xlfn.XLOOKUP($W32&AD$4,braves_19_25!$B:$B&braves_19_25!$C:$C,braves_19_25!$R:$R),0)} -> 0.0057712487 | AE32: {=IFERROR(_xlfn.XLOOKUP($W32&AE$4,braves_19_25!$B:$B&braves_19_25!$C:$C,braves_19_25!$R:$R),0)} -> 0.29958027 | ... AM32: {=IFERROR(_xlfn.XLOOKUP($W32&AM$4,braves_19_25!$B:$B&braves_19_25!$C:$C,braves_19_25!$R:$R),0)} -> 0 | AN32: {=SQRT( MMULT( MMULT( $X32:$AM32, $F$5:$U$20 ), TRANSPOSE($X32:$AM32) ) )} -> 0.59354779
A33: Schwellenbach, Spencer | W33: Tonkin, Michael | X33: {=IFERROR(_xlfn.XLOOKUP($W33&X$4,braves_19_25!$B:$B&braves_19_25!$C:$C,braves_19_25!$R:$R),0)} -> 0.61184723 | Y33: {=IFERROR(_xlfn.XLOOKUP($W33&Y$4,braves_19_25!$B:$B&braves_19_25!$C:$C,braves_19_25!$R:$R),0)} -> 0 | Z33: {=IFERROR(_xlfn.XLOOKUP($W33&Z$4,braves_19_25!$B:$B&braves_19_25!$C:$C,braves_19_25!$R:$R),0)} -> 0.3725643 | AA33: {=IFERROR(_xlfn.XLOOKUP($W33&AA$4,braves_19_25!$B:$B&braves_19_25!$C:$C,braves_19_25!$R:$R),0)} -> 0 | AB33: {=IFERROR(_xlfn.XLOOKUP($W33&AB$4,braves_19_25!$B:$B&braves_19_25!$C:$C,braves_19_25!$R:$R),0)} -> 0 | AC33: {=IFERROR(_xlfn.XLOOKUP($W33&AC$4,braves_19_25!$B:$B&braves_19_25!$C:$C,braves_19_25!$R:$R),0)} -> 0 | AD33: {=IFERROR(_xlfn.XLOOKUP($W33&AD$4,braves_19_25!$B:$B&braves_19_25!$C:$C,braves_19_25!$R:$R),0)} -> 0 | AE33: {=IFERROR(_xlfn.XLOOKUP($W33&AE$4,braves_19_25!$B:$B&braves_19_25!$C:$C,braves_19_25!$R:$R),0)} -> 0.015588465 | ... AM33: {=IFERROR(_xlfn.XLOOKUP($W33&AM$4,braves_19_25!$B:$B&braves_19_25!$C:$C,braves_19_25!$R:$R),0)} -> 0 | AN33: {=SQRT( MMULT( MMULT( $X33:$AM33, $F$5:$U$20 ), TRANSPOSE($X33:$AM33) ) )} -> 0.72217379
